Workbook

Sheet Index
B6: Blume Ventures Investment Profile
B7: Updated as of: | C7: December 2025
A9: A. | B9: Fund I
A10: B. | B10: Fund IA
A11: C. | B11: Fund II
A12: D. | B12: Fund III
A13: E. | B13: Fund IV
A14: F. | B14: Fund IIA
A15: G. | B15: Fund IIB
A16: H. | B16: Fund 1X
A17: I. | B17: Fund 1Y
A18: J. | B18: Fund V
B20: Notes:
B21: - All information in this file is updated as of the last reporting quarter i.e | E21: =C7 -> December 2025
B22: - INR Cashflows have been converted to USD using FX rates on each transaction date/quarter end date as applicable, and vice-versa
B23: USD / INR | C23: 83.4534 | D23: Rate as on quarter end | E23: 30th Jun'24
D24: FX Rate as on 28th June 2024

Sheet Fund I
B2: # | C2: Company | D2: Business / Brand | E2: Geography | F2: Sector | G2: Date | H2: Stage at Entry | I2: Current Stage | J2: Entry Valuation | K2: Last Round Valuation | L2: Valuation used for Mark to Market | M2: Discount to last round | N2: Effective Valuation for Mark-to-market | O2: Valuation Basis | P2: Total Invested Cost | Q2: Residual Cost | R2: Stake (At Entry) | S2: Stake (Current) | T2: Total Value | U2: Unrealised Value | V2: Realised Value | W2: Gross MOIC | X2: Gross IRR (₹) | Y2: If Exited, Mode of Exit | Z2: GP Exit MOIC | AA2: Value Creation by Fund | AB2: Co-investor(s) | AC2: Sourcing Route | AD2: Deal Source | AE2: Deal Lead | AF2: Status
G3: MM/YY | J3: ₹ Mn | K3: ₹ Mn | L3: ₹ Mn | N3: ₹ Mn | P3: ₹ Mn | Q3: ₹ Mn | R3: % | S3: % | T3: ₹ Mn | U3: ₹ Mn | V3: ₹ Mn | W3: x | X3: %
B4: 1 | C4: GreyOrange Robotics International Inc | D4: GreyOrange Robotics | E4: USA | F4: DeepTech | G4: 41177 | H4: Seed | I4: Series D | J4: 121.74923 | K4: 41634.55 | L4: =K4 -> 41634.55 | M4: 0.3 | N4: =L4*(1-M4) -> 29144.185 | O4: Valued at 30% discount to the last round (pre-money) | P4: 22.2 | Q4: 14.59634 | R4: 0.07749688 | S4: 0.014505105 | T4: =U4+V4 -> 1233.2587 | U4: 443.11442 | V4: 790.14431 | W4: =T4/P4 -> 55.552195 | X4: 0.5934786 | Y4: Partial exit - sale to Fund 1X | Z4: =V4/(P4-Q4) -> 103.91632 | AA4: Business Development connects, Investor connect, Finance & compliance support | AB4: Mithril Capital, Pavilion Capital, Binny Bansal, Antehelion Capital, H&M | AC4: Alumni network of GPs ( BITS alum connected through Sanjay) | AD4: Sanjay | AE4: Karthik | AF4: Partial Exit
B5: 2 | C5: Carbon Clean Solutions Pvt Ltd. | D5: Carbon Clean Solutions | E5: Mumbai | F5: CleanTech | G5: 40632 | H5: Seed | I5: Series C | J5: 149.0364 | K5: 48917.542 | L5: 37628.879 | M5: 0.15 | N5: =L5*(1-M5) -> 31984.547 | O5: Valued at a 50% discount to the secondary price of the last round | P5: 13.5 | Q5: 1.1124059 | R5: 0.090581898 | S5: 0.0017580433 | T5: =U5+V5 -> 935.57901 | U5: 40.342124 | V5: 895.23688 | W5: =T5/P5 -> 69.302149 | X5: 0.41588795 | Y5: Partial exit - Secondary sale to Chevron & CMA + Fund 1Y | Z5: =V5/(P5-Q5) -> 72.268826 | AA5: Business Development connects, structuring of the business as a UK domiciled entity , finance and compliance support, hiring | AB5: Chevron, Wave Equity Partners, Marubeni, Samsung Ventures, Saudi Aramco Energy Ventures, CEMEX | AC5: LP referral | AD5: Sanjay | AE5: Karthik | AF5: Partial Exit
B6: 3 | C6: Manash Lifestyle Private Ltd | D6: Purplle | E6: Mumbai | F6: E-Commerce | G6: 41472 | H6: Seed | I6: N.A | J6: 117.26804 | K6: N.A | L6: N.A | M6: 0 | N6: =M6 -> 0 | O6: Exit Value | P6: 12 | Q6: 0 | R6: 0.0731 | S6: N.A | T6: =U6+V6 -> 387.83128 | U6: 0 | V6: 387.83128 | W6: =T6/P6 -> 32.319273 | X6: 0.6296011 | Y6: Sale to Fund 1X | Z6: =V6/P6 -> 32.319273 | AA6: Business Development connects, Investor connect, finance and compliance support, hiring , strategic media arrangement | AB6: Goldman Sachs, Verlinvest, IvyCap, JSW Ventures | AC6: Angel Network | AD6: Karthik | AE6: Ashish | AF6: Exited
B7: 4 | C7: Dataweave Software Private Ltd | D7: Dataweave | E7: USA | F7: Analytics | G7: 41551 | H7: Seed | I7: Series A1 | J7: 382.8 | K7: 969.68 | L7: =K7 -> 969.68 | M7: 1 | N7: =L7*(1-M7) -> 0 | O7: Provisioned - 100% | P7: 6.961133 | Q7: 0 | R7: 0.075268817 | S7: 0.045927102 | T7: =U7+V7 -> 0 | U7: 0 | V7: 0 | W7: =T7/P7 -> 0 | X7: NA | AA7: Business Development connects, Investor connect, Structuring of business as a US domiciled entity, finance and compliance support, hiring of CFO | AB7: WaterBridge, WGG, Freakout, Recruit | AC7: Angel Network | AD7: Karthik | AE7: Sanjay | AF7: Provisioned
B8: 5 | C8: Serendipity Infolabs Private Ltd | D8: Taxiforsure | E8: Bengaluru | F8: Urban Mobility | G8: 41047 | H8: Seed | I8: N.A | J8: 127.04805 | K8: N.A | L8: N.A | M8: 0 | N8: =M8 -> 0 | O8: Exit Value | P8: 5.1623762 | Q8: 0 | R8: 0.0197 | S8: N.A | T8: =U8+V8 -> 47.4 | U8: 0 | V8: 47.4 | W8: =T8/P8 -> 9.1818182 | X8: 2.9664272 | Y8: Acquisition by Ola | Z8: =V8/P8 -> 9.1818182 | AA8: Structuring of follow-on rounds and exit transactions, Board participation | AB8: Accel, Helion, Bessemer | AC8: VC referral | AD8: Karthik | AE8: Karthik | AF8: Exited
C9: ANI Technologies Limited | D9: Ola Cabs | E9: Delhi | F9: Urban Mobility | G9: 42097 | H9: N.A | I9: N.A | J9: N.A | K9: N.A | L9: N.A | M9: 0 | N9: =M9 -> 0 | O9: Exit Value | P9: 12.437624 | Q9: 0 | R9: N.A | S9: N.A | T9: =U9+V9 -> 120.474 | U9: 0 | V9: 120.474 | W9: =T9/P9 -> 9.6862554 | X9: 0.52789122 | Y9: Secondary Sale to Temasek | Z9: =V9/P9 -> 9.6862554 | AB9: Softbank, Tiger Global, Falcon Edge, Seqouia, DST Global, Steadview Capital, Accel, Didi Chuxing, GIC, Matrix , RNT Capital | AC9: Swap for holding in TaxiFor Sure | AE9: Karthik | AF9: Exited
B10: 6 | C10: Instamojo Inc | D10: Instamojo | E10: USA | F10: FinTech | G10: 40636 | H10: Seed | I10: N.A | J10: 46.5 | K10: 969.68 | L10: =K10 -> 969.68 | M10: 1 | N10: =L10*(1-M10) -> 0 | O10: Provisioned - 100% | P10: 9.9 | Q10: 0 | R10: 0.075268817 | S10: 0.038717693 | T10: =U10+V10 -> 0 | U10: 0 | V10: 0 | W10: =T10/P10 -> 0 | X10: NA | AA10: Business Development connects , Hiring, Finance & compliance support | AB10: Kalaari Capital, Anypay, 500 Startups | AC10: Founder network ( connected through the founder's prior start-up) | AD10: Karthik | AE10: Karthik | AF10: Provisioned
B11: 7 | C11: E2E Networks Private Limited | D11: E2E Networks | E11: Delhi | F11: SaaS | G11: 41292 | H11: Seed | I11: N.A | J11: 137.50215 | K11: N.A | L11: N.A | M11: 0 | N11: =M11 -> 0 | O11: Exit Value | P11: 8.3 | Q11: 0 | R11: 0.1384 | S11: N.A | T11: =U11+V11 -> 234.30061 | U11: 0 | V11: 234.30061 | W11: =T11/P11 -> 28.228989 | X11: 0.45172761 | Y11: Exit via OFS in IPO and Public market | Z11: =V11/P11 -> 28.228989 | AA11: Venture debt, Support with IPO process, investor connects for IPO, business development connects , hiring | AC11: Referral by co-investor | AD11: Karthik | AE11: Ashish | AF11: Exited
B12: 8 | C12: Exotel Techcom Pvt. Ltd | D12: Exotel | E12: Bengaluru | F12: ='Fund 1X'!F6 -> SaaS | G12: 41096 | H12: Seed | I12: N.A | J12: 74.115367 | K12: N.A | L12: N.A | M12: 0 | N12: =M12 -> 0 | O12: Exit Value | P12: 10 | Q12: 0 | R12: 0.12 | S12: N.A | T12: =U12+V12 -> 199.34942 | U12: 0 | V12: 199.34942 | W12: =T12/P12 -> 19.934942 | X12: 0.43172993 | Y12: Sale to Fund 1X | Z12: =V12/P12 -> 19.934942 | AA12: Board participation, Business Development connects, Hiring | AB12: Mumbai Angels | AC12: Angel Network | AD12: Karthik | AE12: Karthik | AF12: Exited
B13: 9 | C13: Baldor Technologies Private Ltd | D13: Idfy | E13: Mumbai | F13: FinTech | G13: 41046 | H13: Seed | I13: N.A | J13: 57.767017 | K13: N.A | L13: N.A | M13: 0 | N13: =M13 -> 0 | O13: Exit Value | P13: 11.2 | Q13: 0 | R13: 0.098787497 | S13: N.A | T13: =U13+V13 -> 157.90365 | U13: 0 | V13: 157.90365 | W13: =T13/P13 -> 14.09854 | X13: 0.39209596 | Y13: Sale to Fund 1X | Z13: =V13/P13 -> 14.09854 | AA13: Business Development connects, Investor connect, hiring | AB13: MegaDelta, Dream Incubator | AC13: co-investor network - angel | AD13: Karthik | AE13: Karthik | AF13: Exited
B14: 10 | C14: Solvy Tech Solutions Pvt. Ltd | D14: Zopper | E14: Delhi | F14: FinTech | G14: 41367 | H14: Seed | I14: N.A | J14: 28.484574 | K14: N.A | L14: N.A | M14: 0 | N14: =M14 -> 0 | O14: Exit Value | P14: 18.5 | Q14: 0 | R14: 0.08116874 | S14: N.A | T14: =U14+V14 -> 387.62304 | U14: 0 | V14: 387.62304 | W14: =T14/P14 -> 20.952597 | X14: 0.37970463 | Y14: Sale to Fund 1Y | Z14: =V14/P14 -> 20.952597 | AA14: Sourcing of follow-on round investors, Finance and compliance support, assistance with M&A transactions , hiring | AB14: Tiger Global, Nirvana | AC14: Alumni network of GPs | AD14: Karthik | AE14: Karthik | AF14: Exited
B15: 11 | C15: Social Audience Private Ltd | D15: TookiTaki | E15: Bengaluru | F15: FinTech | G15: 41477 | H15: Seed | I15: N.A | J15: 122.28 | K15: 361.8393 | L15: =K15 -> 361.8393 | M15: 1 | N15: =L15*(1-M15) -> 0 | O15: Provisioned - 100% | P15: 4.8 | Q15: 0 | R15: 0.11835759 | S15: 0.0016 | T15: =U15+V15 -> 0 | U15: 0 | V15: 0 | W15: =T15/P15 -> 0 | X15: NA | AA15: Hiring, Finance & compliance support | AB15: Jungle Ventures, Rebright, Illuminate Financial | AC15: Referral by co-investor | AD15: Sanjay | AE15: Sanjay | AF15: Provisioned
B16: 12 | C16: Induslynk Training Services Pvt. Ltd. | D16: Mettl | E16: Delhi | F16: HRTech | G16: 40636 | H16: Seed | I16: N.A | J16: 112.27979 | K16: N.A | L16: N.A | M16: 0 | N16: =M16 -> 0 | O16: Exit Value | P16: 34 | Q16: 0 | R16: 0.089108358 | S16: N.A | T16: =U16+V16 -> 210.26103 | U16: 0 | V16: 210.26103 | W16: =T16/P16 -> 6.1841478 | X16: 0.34323018 | Y16: Acquisition by Mercer | Z16: =V16/P16 -> 6.1841478 | AA16: Follow-on investsor connect, finance and compliance support , business development connects, hiring | AB16: Kalaari | AC16: Founder network ( Inmobi founder ) | AD16: Sanjay | AE16: Karthik | AF16: Exited
B17: 13 | C17: ZipDial Mobile Solution Private Limited | D17: Zip Dial | E17: Bengaluru | F17: SaaS | G17: 40659 | H17: Seed | I17: N.A | J17: 122.28 | K17: N.A | L17: N.A | M17: 0 | N17: =M17 -> 0 | O17: Exit Value | P17: 15.5 | Q17: 0 | R17: 0.0245 | S17: N.A | T17: =U17+V17 -> 80.3 | U17: 0 | V17: 80.3 | W17: =T17/P17 -> 5.1806452 | X17: 0.61345489 | Y17: Acquisition by Twitter | Z17: =V17/P17 -> 5.1806452 | AA17: Introduction to follow-on round investors, Board participation | AB17: DSG, 500 Startups, Jungle Ventures, Times Internet, Unilazer | AC17: Angel Network | AD17: Karthik | AE17: Karthik | AF17: Exited
B18: 14 | C18: Webklipper Technologies Pvt. Ltd | D18: Webengage | E18: Mumbai | F18: SaaS | G18: 41257 | H18: Seed | I18: N.A | J18: 166.668 | K18: N.A | L18: N.A | M18: 0 | N18: =M18 -> 0 | O18: Exit Value | P18: 21.292777 | Q18: 0 | R18: 0.0605 | S18: N.A | T18: =U18+V18 -> 82.680533 | U18: 0 | V18: 82.680533 | W18: =T18/P18 -> 3.8830319 | X18: 0.20506152 | Y18: Sale to Fund 1X | Z18: =V18/P18 -> 3.8830319 | AA18: Board participation, Business Development connects, evaluating collaborations and acqui-hires from time to time, Hiring, Finance & compliance support | AB18: GTI Capital, IQ Capital, IAN | AC18: Referral by co-investor | AD18: Karthik | AE18: Karthik | AF18: Exited
B19: 15 | C19: Adepto Solutions Private Ltd | D19: Adepto | E19: Bengaluru | F19: AdTech | G19: 40746 | H19: Seed | I19: N.A | J19: 47.3 | K19: N.A | L19: N.A | M19: 0 | N19: =M19 -> 0 | O19: Written Off | P19: 11 | Q19: 0 | R19: 0.12675053 | S19: N.A | T19: =U19+V19 -> 0.00177 | U19: 0 | V19: 0.00177 | W19: =T19/P19 -> 0.00016090909 | X19: NA | AC19: Co-investor referral ( angel investor) | AD19: Karthik | AE19: Karthik | AF19: Written Off
C20: Kuliza Technologies Pvt. Ltd | D20: Kuliza | E20: Bengaluru | F20: FinTech | G20: 41485 | H20: Seed | I20: N.A | J20: N.A | K20: N.A | L20: N.A | M20: 0 | N20: =M20 -> 0 | O20: Provisioned - 100% | P20: 5 | Q20: 0 | R20: 0.070800706 | S20: N.A | T20: =U20+V20 -> 0 | U20: 0 | V20: 0 | W20: =T20/P20 -> 0 | X20: NA | AA20: Facilitating M&A, Finance and compliance support, business development connects | AB20: Emergent Ventures | AC20: Swap of shares of Adepto | AD20: Karthik | AE20: Ashish | AF20: Provisioned
B21: 16 | C21: Greytip Software Private Ltd | D21: Greytip | E21: Bengaluru | F21: HRTech | G21: 41607 | H21: Seed | I21: Series E | J21: 319.99753 | K21: N.A | L21: N.A | M21: 0 | N21: 0 | O21: Exit Value | P21: 21.000682 | Q21: 0 | R21: 0.049903462 | S21: 0.02628157 | T21: =U21+V21 -> 189.8619 | U21: 0 | V21: 189.8619 | W21: =T21/P21 -> 9.0407493 | X21: 0.24203198 | Y21: Secondary sale to Apax Partners | Z21: =V21/P21 -> 9.0407493 | AA21: support for venture debt, structuring of follow-on round, Business Development connects , Hiring, Finance & compliance support | AB21: MegaDelta, InfoEdge, GMO | AC21: Ecosystem referral | AD21: Karthik | AE21: Karthik | AF21: Exited
B22: 17 | C22: Promptec Renewable Energy Solutions Private Limited | D22: Prompt Renewables | E22: Bengaluru | F22: CleanTech | G22: 40627 | H22: Seed | I22: N.A | J22: 90 | K22: N.A | L22: N.A | M22: 0 | N22: =M22 -> 0 | O22: Exit Value | P22: 45 | Q22: 0 | R22: 0.055555576 | S22: N.A | T22: =U22+V22 -> 97.239294 | U22: 0 | V22: 97.239294 | W22: =T22/P22 -> 2.1608732 | X22: 0.28793276 | Y22: Acquisition by Havells | Z22: =V22/P22 -> 2.1608732 | AA22: Business Development connects, facilitating / helping in M&A, general counsel | AC22: Alumni network of GPs ( Karthik's alum introduced to the founder ) | AD22: Karthik | AE22: Karthik | AF22: Exited
B23: 18 | C23: Turtle Yogi Technologies Private Ltd | D23: 1Click (Turtleyogi) | E23: Bengaluru | F23: Digital media | G23: 41433 | H23: Seed | I23: N.A | J23: 30 | K23: N.A | L23: N.A | M23: 0 | N23: =M23 -> 0 | O23: Exit Value | P23: 4.8 | Q23: 0 | R23: 0.14250239 | S23: N.A | T23: =U23+V23 -> 7.9 | U23: 0 | V23: 7.9 | W23: =T23/P23 -> 1.6458333 | X23: 0.38133907 | Y23: Acquisition by Freshworks | Z23: =V23/P23 -> 1.6458333 | AA23: Finance and compliance, business development , connect with strategic collaborator , structuring of exit transaction | AC23: Angel Network | AD23: Karthik | AE23: Ashish | AF23: Exited
B24: 19 | C24: Threadsol Software Private Ltd | D24: Threadsol | E24: Delhi | F24: SaaS | G24: 41631 | H24: Seed | I24: N.A | J24: 52 | K24: N.A | L24: N.A | M24: 0 | N24: =M24 -> 0 | O24: Exit Value | P24: 13.891466 | Q24: 0 | R24: 0.1 | S24: N.A | T24: =U24+V24 -> 20.700262 | U24: 0 | V24: 20.700262 | W24: =T24/P24 -> 1.4901424 | X24: 0.10671253 | Y24: Acquisition by Coates Plc | Z24: =V24/P24 -> 1.4901424 | AA24: Business Development connects, Investor connect, Structuring of business as a SG domiciled entity, finance and compliance, Hiring , structuring of exit transaction | AB24: Catamaran Ventures | AC24: Angel Network | AD24: Karthik | AE24: Ashish | AF24: Exited
B25: 20 | C25: Newgen Internet Networks Pvt. Ltd | D25: Glamrs | E25: Mumbai | F25: Digital Media | G25: 41096 | H25: Seed | I25: N.A | J25: 89.96736 | K25: N.A | L25: N.A | M25: 0 | N25: =M25 -> 0 | O25: Exit Value | P25: 19 | Q25: 0 | R25: 0.11115142 | S25: N.A | T25: =U25+V25 -> 28.5 | U25: 0 | V25: 28.5 | W25: =T25/P25 -> 1.5 | X25: 0.046158484 | Y25: Acquisition by Purplle | Z25: =V25/P25 -> 1.5 | AA25: Business Development connects, Investor connect, finance and compliance, Hiring | AC25: Founder network | AD25: Karthik | AE25: Ashish | AF25: Exited
B26: 21 | C26: Spunk Media Private Ltd | D26: Qubecell | E26: Mumbai | F26: FinTech | G26: 41458 | H26: Seed | I26: N.A | J26: 63.25 | K26: N.A | L26: N.A | M26: 0 | N26: =M26 -> 0 | O26: Exit Value | P26: 3.5 | Q26: 0 | R26: 0.055335966 | S26: N.A | T26: =U26+V26 -> 5.1 | U26: 0 | V26: 5.1 | W26: =T26/P26 -> 1.4571429 | X26: 0.60094962 | Y26: Acquisition by Boku | Z26: =V26/P26 -> 1.4571429 | AB26: Kae Capital | AC26: Angel Network | AD26: Karthik | AE26: Adit* | AF26: Exited
B27: 22 | C27: Nowfloats Technologies Private Ltd | D27: Nowfloats | E27: Hyderabad | F27: SaaS | G27: 41439 | H27: Seed | I27: N.A | J27: 99.222222 | K27: N.A | L27: N.A | M27: 0 | N27: =M27 -> 0 | O27: Exit Value | P27: 13.48784 | Q27: 0 | R27: 0.0504 | S27: N.A | T27: =U27+V27 -> 17.265207 | U27: 0 | V27: 17.265207 | W27: =T27/P27 -> 1.2800572 | X27: 0.047209263 | Y27: Acquisition by Reliance Jio | Z27: =V27/P27 -> 1.2800572 | AA27: Business Development connects, Investor connect, finance and compliance, hiring | AB27: Omidyar, IIFL, Iron Pillar | AC27: Angel Network | AD27: Karthik | AE27: Ashish | AF27: Exited
B28: 23 | C28: Framebench Technologies Pvt. Ltd. | D28: Framebench | E28: Bengaluru | F28: Digital media | G28: 41082 | H28: Seed | I28: N.A | J28: 30.55 | K28: N.A | L28: N.A | M28: 0 | N28: =M28 -> 0 | O28: Exit Value | P28: 4.04 | Q28: 0 | R28: 0.1487 | S28: N.A | T28: =U28+V28 -> 4 | U28: 0 | V28: 4 | W28: =T28/P28 -> 0.99009901 | X28: -0.0026144622 | Y28: Acquisition by Freshworks | Z28: =V28/P28 -> 0.99009901 | AA28: Sourcing of follow-on round investors, Finance and compliance support, assistance with M&A transactions | AC28: Alumni network of GPs ( BITS alum connected throigh Sanjay) | AD28: Sanjay | AE28: Sanjay | AF28: Exited
B29: 24 | C29: Printo Document Services Private Ltd | D29: Printo | E29: Bengaluru | F29: E-Commerce | G29: 41162 | H29: Seed | I29: Series C1 | J29: 124.98675 | K29: 1063.8298 | L29: =K29 -> 1063.8298 | M29: 1 | N29: =L29*(1-M29) -> 0 | O29: Provisioned - 100% | P29: 15 | Q29: 0 | R29: 0.060006361 | S29: 0.0392 | T29: =U29+V29 -> 0 | U29: 0 | V29: 0 | W29: =T29/P29 -> 0 | X29: NA | AA29: Board participation, Business Development connects, evaluating collaborations and acqui-hires from time to time | AB29: Infoedge | AC29: Fund advisor's referral | AD29: Karthik | AE29: Karthik | AF29: Provisioned
B30: 25 | C30: HMS Infotech Private Ltd /Hotelogix Pte Limited | D30: Hotelogix | E30: Bengaluru | F30: Consumer Services | G30: 41004 | H30: Seed | I30: Series C | J30: 96.5 | K30: 1042.0633 | L30: =K30 -> 1042.0633 | M30: 1 | N30: =L30*(1-M30) -> 0 | O30: Provisioned - 100% | P30: 13.862911 | Q30: 0 | R30: 0.025890801 | S30: 0.015292786 | T30: =U30+V30 -> 0 | U30: 0 | V30: 0 | W30: =T30/P30 -> 0 | X30: NA | AA30: Board participation, cross-border structuring support , Finance & compliance support | AB30: Accel, Saama, Vertex | AC30: angel ecosystem | AD30: Karthik | AE30: Sanjay | AF30: Provisioned
B31: 26 | C31: Nivaata Systems Private Ltd | D31: Nivaata | E31: Bengaluru | F31: Urban Mobility | G31: 40919 | H31: Seed | I31: Pre Series C | J31: 109.12997 | K31: 8762 | L31: =K31 -> 8762 | M31: 1 | N31: =L31*(1-M31) -> 0 | O31: Provisioned - 100% | P31: 23.686624 | Q31: 0 | R31: 0.079264284 | S31: 0.077865743 | T31: =U31+V31 -> 0 | U31: 0 | V31: 0 | W31: =T31/P31 -> 0 | X31: NA | AA31: Strategy, Business Development connects, Hiring including sourcing of CXO | AB31: Bosch, Mayfield, GWB Group, VAMM Ventures | AC31: Eco-system referral | AD31: Karthik | AE31: Ashish | AF31: Provisioned
B32: 27 | C32: Chaitanya India Fin Credit Private Limited | D32: Chaitanya India | E32: Bengaluru | F32: FinTech | G32: 40578 | H32: Seed | I32: N.A | J32: 165.3 | K32: N.A | L32: N.A | M32: 0 | N32: =M32 -> 0 | O32: Exit Value | P32: 3.6 | Q32: 0 | R32: 0.021778584 | S32: N.A | T32: =U32+V32 -> 3.6 | U32: 0 | V32: 3.6 | W32: =T32/P32 -> 1 | X32: 4.8828125e-09 | Y32: Buyback | Z32: =V32/P32 -> 1 | AC32: Founder network | AD32: Karthik | AE32: Karthik | AF32: Exited
B33: 28 | C33: Valgen Infosystem Pvt Ltd. | D33: Valgen Infosystems | E33: Chennai | F33: RetailTech | G33: 40636 | H33: Seed | I33: N.A | J33: 69.9996 | K33: N.A | L33: N.A | M33: 0 | N33: =M33 -> 0 | O33: Exit Value | P33: 10.625 | Q33: 0 | R33: 0.10714347 | S33: N.A | T33: =U33+V33 -> 9.7394 | U33: 0 | V33: 9.7394 | W33: =T33/P33 -> 0.91664941 | X33: -0.009878268 | Y33: Acqusition by CloudCherry | Z33: =V33/P33 -> 0.91664941 | AC33: VC referral | AD33: Karthik | AE33: Karthik | AF33: Exited
B34: 29 | C34: WAH Holidays Private Ltd | D34: WeAreHolidays | E34: Delhi | F34: Consumer Services | G34: 41358 | H34: Seed | I34: N.A | J34: 55.2784 | K34: N.A | L34: N.A | M34: 0 | N34: =M34 -> 0 | O34: Written Off | P34: 7.5 | Q34: 0 | R34: 0.045269038 | S34: N.A | T34: =U34+V34 -> 2.7 | U34: 0 | V34: 2.7 | W34: =T34/P34 -> 0.36 | X34: NA | Z34: =V34/P34 -> 0.36 | AA34: Business Development connects, Finance and compliance support, Board participation, hiring, structuring of follow-on rounds | AB34: Matrix, Mumbai Angels | AC34: Angel Network | AD34: Sanjay | AE34: Karthik | AF34: Written Off
B35: 30 | C35: Karmic Labs Pvt.Ltd. | D35: Karmic | E35: Mumbai | F35: Life Sciences | G35: 40785 | H35: Seed | I35: N.A | J35: 51.047856 | K35: N.A | L35: N.A | M35: 0 | N35: =M35 -> 0 | O35: Written Off | P35: 10 | Q35: 0 | R35: 0.19594078 | S35: N.A | T35: =U35+V35 -> 2.8 | U35: 0 | V35: 2.8 | W35: =T35/P35 -> 0.28 | X35: NA | Z35: =V35/P35 -> 0.28 | AB35: Mumbai Angels, IAN | AC35: Angel Network | AD35: Karthik | AE35: Karthik | AF35: Written Off
B36: 31 | C36: Rolocule Games Pvt. Ltd | D36: Rolocule | E36: Pune | F36: Digital Media | G36: 41003 | H36: Seed | I36: N.A | J36: 62.6 | K36: N.A | L36: N.A | M36: 0 | N36: =M36 -> 0 | O36: Written Off | P36: 29.63569 | Q36: 0 | R36: 0.036817256 | S36: N.A | T36: =U36+V36 -> 7.486435 | U36: 0 | V36: 7.486435 | W36: =T36/P36 -> 0.25261551 | X36: NA | Z36: =V36/P36 -> 0.25261551 | AA36: Board participation, Finance and compliance support, facilitating co-founder split amicably | AB36: Mumbai Angels | AC36: Angel Network | AD36: Karthik | AE36: Karthik | AF36: Written Off
B37: 32 | C37: Shantani Proteome Analytics Pvt. Ltd | D37: Shantani | E37: Pune | F37: Life Sciences | G37: 41059 | H37: Seed | I37: N.A | J37: 44.76496 | K37: N.A | L37: N.A | M37: 0 | N37: =M37 -> 0 | O37: Written Off | P37: 8.8 | Q37: 0 | R37: 0.1116945 | S37: N.A | T37: =U37+V37 -> 1.74379 | U37: 0 | V37: 1.74379 | W37: =T37/P37 -> 0.19815795 | X37: NA | Z37: =V37/P37 -> 0.19815795 | AA37: Finance & compliance support | AB37: India Innovation Fund | AC37: Referral by co-investor | AD37: Karthik | AE37: Karthik | AF37: Written Off
B38: 33 | C38: RupeeStreet Financial Services Pvt Ltd. | D38: Moneysights | E38: Bengaluru | F38: FinTech | G38: 40850 | H38: Seed | I38: N.A | J38: 135 | K38: N.A | L38: N.A | M38: 0 | N38: =M38 -> 0 | O38: Written Off | P38: 11.999205 | Q38: 0 | R38: 0.074074074 | S38: N.A | T38: =U38+V38 -> 2.0098 | U38: 0 | V38: 2.0098 | W38: =T38/P38 -> 0.16749443 | X38: NA | Z38: =V38/P38 -> 0.16749443 | AA38: Introduction to follow-on round investors | AC38: Founder network ( connected through the founder’s prior start-up) | AD38: Sanjay | AE38: Sanjay | AF38: Written Off
B39: 34 | C39: Eki Communications Pvt Ltd | D39: Survelytics | E39: Mumbai | F39: MarketingTech | G39: 40654 | H39: Seed | I39: N.A | J39: 37.5 | K39: N.A | L39: N.A | M39: 0 | N39: =M39 -> 0 | O39: Written Off | P39: 5.5 | Q39: 0 | R39: 0.13333333 | S39: N.A | T39: =U39+V39 -> 0.002088 | U39: 0 | V39: 0.002088 | W39: =T39/P39 -> 0.00037963636 | X39: NA | Z39: =V39/P39 -> 0.00037963636 | AA39: Compliance support | AC39: Referral by co-investor | AD39: Sanjay | AE39: Sanjay | AF39: Written Off
B40: 35 | C40: Retail Quotient Research Pvt.Ltd | D40: RedQuanta | E40: Mumbai | F40: RetailTech | G40: 41142 | H40: Seed | I40: N.A | J40: 65.2 | K40: N.A | L40: N.A | M40: 0 | N40: =M40 -> 0 | O40: Written Off | P40: 5.484572 | Q40: 0 | R40: 0.053666542 | S40: N.A | T40: =U40+V40 -> 0.01276 | U40: 0 | V40: 0.01276 | W40: =T40/P40 -> 0.0023265261 | X40: NA | Z40: =V40/P40 -> 0.0023265261 | AC40: Accelerator network | AD40: Karthik | AE40: Sajid Fazalbhoy* | AF40: Written Off
B41: 36 | C41: 21Trends Private Ltd | D41: VoxPop | E41: Mumbai | F41: E-Commerce | G41: 41478 | H41: Seed | I41: N.A | J41: 30 | K41: N.A | L41: N.A | M41: 0 | N41: =M41 -> 0 | O41: Written Off | P41: 7.5 | Q41: 0 | R41: 0.25 | S41: N.A | T41: =U41+V41 -> 0.008286 | U41: 0 | V41: 0.008286 | W41: =T41/P41 -> 0.0011048 | X41: NA | Z41: =V41/P41 -> 0.0011048 | AA41: Facilitating collaboration with strategic investor, strategic media arrangement, Finance & compliance support | AC41: Founder network | AD41: Karthik | AE41: Ashish | AF41: Written Off
...

Sheet Fund IA
B2: # | C2: Company | D2: Business / Brand | E2: Geography | F2: Sector | G2: Date | H2: Stage at Entry | I2: Current Stage | J2: Entry Valuation | K2: Last Round Valuation | L2: Valuation used for Mark to Market | M2: Discount to last round | N2: Effective Valuation for Mark-to-market | O2: Valuation Basis | P2: Total Invested Cost | Q2: Residual Cost | R2: Stake (At Entry) | S2: Stake (Current) | T2: Total Value | U2: Unrealised Value | V2: Realised Value | W2: Gross MOIC | X2: Gross IRR (₹) | Y2: If Exited, Mode of Exit | Z2: GP Exit MOIC | AA2: Value Creation by Fund | AB2: Co-investor(s) | AC2: Sourcing Route | AD2: Deal Source | AE2: Deal Lead | AF2: Status
G3: MM/YY | J3: ₹ Mn | K3: ₹ Mn | L3: ₹ Mn | N3: ₹ Mn | P3: ₹ Mn | Q3: ₹ Mn | R3: % | S3: % | T3: ₹ Mn | U3: ₹ Mn | V3: ₹ Mn | W3: x | X3: %
B4: 1 | C4: Fintech Solutions Private Limited | D4: Turtlemint | E4: Mumbai | F4: FinTech | G4: 42121 | H4: Seed | I4: N.A | J4: 114.5004 | K4: N.A | L4: N.A | M4: 0 | N4: 0 | O4: Exit Value | P4: 28.268405 | Q4: 0 | R4: 0.05240724 | S4: N.A | T4: =V4+U4 -> 540.55268 | U4: 0 | V4: 540.55268 | W4: =T4/P4 -> 19.12215 | X4: 0.70132714 | Y4: Sale to Fund 1X | Z4: =W4 -> 19.12215 | AA4: Investor connect, Finance and compliance support, hiring | AB4: Sequoia, Nexus, AMFAM, Mass Mutual, Jungle Ventures, GGV, SIG | AC4: Personal network of team member | AD4: Adit* | AE4: Ashish | AF4: Exited
B5: 2 | C5: GreyOrange Robotics International Inc | D5: GreyOrange Robotics | E5: USA | F5: DeepTech | G5: 42065 | H5: Series A - Secondary | I5: Series D | J5: 1423.7105 | K5: 41634.55 | L5: 41634.55 | M5: 0.3 | N5: =L5*(1-M5) -> 29144.185 | O5: Valued at 30% discount to the last round(pre-money) | P5: 9.4 | Q5: 6.5608785 | R5: 0.0064078532 | S5: 0.0014480418 | T5: =V5+U5 -> 110.63236 | U5: 45.116943 | V5: 65.515417 | W5: =T5/P5 -> 11.7694 | X5: 0.36874811 | Y5: Partial sale to Fund 1X | Z5: =V5/(P5-Q5) -> 23.075947 | AA5: Business Development connects, Investor connect, Finance & compliance support | AB5: Mithril Capital, Pavilion Capital, Binny Bansal, Antehelion Capital, H&M | AC5: Alumni network of GPs ( BITS alum connected through Sanjay) | AD5: Sanjay | AE5: Karthik | AF5: Partial Exit
B6: 3 | C6: Stelling Technologies Private Limited | D6: IntrCity | E6: Delhi | F6: Consumer Services | G6: 41892 | H6: Seed | I6: N.A | J6: 132.01616 | K6: N.A | L6: =K6 -> N.A | M6: 0 | N6: =M6 -> 0 | O6: Exit Value | P6: 15.4 | Q6: 0 | R6: 0.045575758 | S6: N.A | T6: =V6+U6 -> 183.83928 | U6: 0 | V6: 183.83928 | W6: =T6/P6 -> 11.937616 | X6: 0.30894382 | Y6: Sale to Fund 1Y | Z6: =W6 -> 11.937616 | AA6: Board participation, connects to follow-on round investors, support on M&A, structuring of rounds, general counsel, Hiring, Finance & compliance support | AB6: Mirablis Investment Trust, Helion, Omidyar, NRJN (Nandan Nilekeni) | AC6: LP referral | AD6: Karthik | AE6: Karthik | AF6: Exited
B7: 4 | C7: Manash Lifestyle Private Ltd | D7: Purplle | E7: Mumbai | F7: E-Commerce | G7: 42326 | H7: Series A2 | I7: N.A | J7: 1590.2467 | K7: N.A | L7: =K7 -> N.A | M7: 0 | N7: =M7 -> 0 | O7: Exit Value | P7: 6 | Q7: 0 | R7: 0.0037989409 | S7: N.A | T7: =V7+U7 -> 30.003084 | U7: 0 | V7: 30.003084 | W7: =T7/P7 -> 5.000514 | X7: 0.36411879 | Y7: Sale to Fund 1X | Z7: =W7 -> 5.000514 | AA7: Business Development connects, Investor connect, finance and compliance support, hiring , strategic media arrangement | AB7: Goldman Sachs, Verlinvest, IvyCap, JSW Ventures | AC7: Angel Network | AD7: Karthik | AE7: Ashish | AF7: Exited
B8: 5 | C8: E2E Networks Private Limited | D8: E2E Networks | E8: Delhi | F8: SaaS | G8: 41831 | H8: Seed | I8: N.A | J8: 137.50215 | K8: N.A | L8: =K8 -> N.A | M8: 0 | N8: =M8 -> 0 | O8: Exit Value | P8: 9 | Q8: 0 | R8: 0.065454545 | S8: N.A | T8: =V8+U8 -> 105.2576 | U8: 0 | V8: 105.2576 | W8: =T8/P8 -> 11.695289 | X8: 0.35847025 | Y8: Exit via OFS in IPO and Public market | Z8: =W8 -> 11.695289 | AA8: Venture debt, Support with IPO process, investor connects for IPO, business development connects , hiring | AC8: Referral by co-investor | AD8: Karthik | AE8: Ashish | AF8: Exited
B9: 6 | C9: Manak Waste Management Private Limited | D9: Cashify | E9: Delhi | F9: Re-commerce | G9: 42116 | H9: Seed | I9: N.A | J9: 174.00832 | K9: N.A | L9: =K9 -> N.A | M9: 0 | N9: =M9 -> 0 | O9: Exit Value | P9: 36.464294 | Q9: 0 | R9: 0.086236659 | S9: N.A | T9: =V9+U9 -> 496.19465 | U9: 0 | V9: 496.19465 | W9: =T9/P9 -> 13.607686 | X9: 0.52531864 | Y9: Sale to Fund 1Y | Z9: =W9 -> 13.607686 | AA9: Investor connect, Board participation, operations support , finance and complaince support | AB9: Shunwei, Bessemer, CDH, Morningside, AiHuiShou, Olympus Capital | AC9: Personal network of team member | AD9: Arpit | AE9: Arpit | AF9: Exited
B10: 7 | C10: Dataweave Software Private Ltd | D10: Dataweave | E10: USA | F10: Analytics | G10: 42065 | H10: Seed | I10: Series A1 | J10: 382.8 | K10: 53.108753 | L10: 0 | M10: 0 | N10: =M10 -> 0 | O10: Provisioned - 100% | P10: 9.358417 | Q10: =P10 -> 9.358417 | R10: 0.01566092 | S10: 0.013603848 | T10: =V10+U10 -> 0 | U10: 0 | V10: 0 | W10: =T10/P10 -> 0 | X10: NA | AA10: Business Development connects, Investor connect, Structuring of business as a US domiciled entity, finance and compliance support, hiring of CFO | AB10: WaterBridge, WGG, Freakout, Recruit | AC10: Angel Network | AD10: Karthik | AE10: Sanjay | AF10: Provisioned
B11: 8 | C11: ZipDial Mobile Solution Private Limited | D11: ZipDial | E11: Bengaluru | F11: SaaS | G11: 41901 | H11: Seed | I11: N.A | J11: 606.02836 | K11: N.A | L11: =K11 -> N.A | M11: 0 | N11: =M11 -> 0 | O11: Exit Value | P11: 5 | Q11: 0 | R11: 0.0082508251 | S11: N.A | T11: =V11+U11 -> 13.836736 | U11: 0 | V11: 13.836736 | W11: =T11/P11 -> 2.7673472 | X11: 2.0619896 | Y11: Acquisition by Twitter | Z11: =W11 -> 2.7673472 | AA11: Introduction to follow-on round investors, Board participation | AB11: DSG, 500 Startups, Jungle Ventures, Times Internet, Unilazer | AC11: Angel Network | AD11: Karthik | AE11: Karthik | AF11: Exited
B12: 9 | C12: Baldor Technologies Private Ltd | D12: Idfy | E12: Mumbai | F12: FinTech | G12: 42090 | H12: Seed | I12: N.A | J12: 449.67502 | K12: N.A | L12: =K12 -> N.A | M12: 0 | N12: =M12 -> 0 | O12: Exit Value | P12: 12 | Q12: 0 | R12: 0.026664496 | S12: N.A | T12: =V12+U12 -> 29.1906 | U12: 0 | V12: 29.1906 | W12: =T12/P12 -> 2.43255 | X12: 0.16906372 | Y12: Sale to Fund 1X | Z12: =W12 -> 2.43255 | AA12: Business Development connects, Investor connect, hiring | AB12: NEA, Transunion, MegaDelta | AC12: co-investor network - angel | AD12: Karthik | AE12: Karthik | AF12: Exited
B13: 10 | C13: Greytip Software Private Ltd | D13: Greytip | E13: Bengaluru | F13: HRTech | G13: 42206 | H13: Seed | I13: N.A | J13: 876.45223 | K13: N.A | L13: 0 | M13: 0 | N13: =M13 -> 0 | O13: Exit Value | P13: 11.749724 | Q13: 0 | R13: 0.017863523 | S13: N.A | T13: =V13+U13 -> 68.185371 | U13: 0 | V13: 68.185371 | W13: =T13/P13 -> 5.8031466 | X13: 0.21514648 | Y13: Secondary sale to Apax Partners | Z13: =W13 -> 5.8031466 | AA13: support for venture debt, structuring of follow-on round, Business Development connects , Hiring, Finance & compliance support | AB13: MegaDelta, InfoEdge, GMO | AC13: Ecosystem referral | AD13: Karthik | AE13: Karthik | AF13: Exited
B14: 11 | C14: Webklipper Technologies Pvt. Ltd | D14: Webengage | E14: Mumbai | F14: SaaS | G14: 42391 | H14: Seed | I14: N.A | J14: 1000 | K14: N.A | L14: =K14 -> N.A | M14: 0 | N14: =M14 -> 0 | O14: Exit Value | P14: 10 | Q14: 0 | R14: 0.0117 | S14: N.A | T14: =V14+U14 -> 13.440024 | U14: 0 | V14: 13.440024 | W14: =T14/P14 -> 1.3440024 | X14: 0.060844907 | Y14: Sale to Fund 1X | Z14: =W14 -> 1.3440024 | AA14: Board participation, Business Development connects, evaluating collaborations and acqui-hires from time to time, Hiring, Finance & compliance support | AB14: SWC, Singularity, IndiaQuotient | AC14: Referral by co-investor | AD14: Karthik | AE14: Karthik | AF14: Exited
B15: 12 | C15: Nowfloats Technologies Private Ltd | D15: Nowfloats | E15: Hyderabad | F15: SaaS | G15: 41439 | H15: Seed | I15: N.A | J15: 265.79542 | K15: N.A | L15: =K15 -> N.A | M15: 0 | N15: =M15 -> 0 | O15: Exit Value | P15: 16 | Q15: 0 | R15: 0.0148 | S15: N.A | T15: =V15+U15 -> 19.474287 | U15: 0 | V15: 19.474287 | W15: =T15/P15 -> 1.2171429 | X15: 0.046357573 | Y15: Acquisition by Reliance Jio | Z15: =W15 -> 1.2171429 | AA15: Business Development connects, Investor connect, finance and compliance, hiring | AB15: Omidyar, IIFL, Iron Pillar | AC15: Angel Network | AD15: Karthik | AE15: Ashish | AF15: Exited
B16: 13 | C16: Digissential Enterprises Private Limited | D16: Bill Bachao | E16: Bengaluru | F16: ConsumerTech | G16: 41971 | H16: Seed | I16: N.A | J16: 200 | K16: N.A | L16: =K16 -> N.A | M16: 0 | N16: =M16 -> 0 | O16: Exit Value | P16: 10 | Q16: 0 | R16: 0.05 | S16: N.A | T16: =V16+U16 -> 9.92581 | U16: 0 | V16: 9.92581 | W16: =T16/P16 -> 0.992581 | X16: -0.014679208 | Y16: Buyback | Z16: =W16 -> 0.992581 | AA16: Board participation, exit structuring | AC16: Founder was connected to the GPs through his earlier stint with Vodafone | AD16: Karthik | AE16: Karthik | AF16: Exited
B17: 14 | C17: Threadsol Software Private Ltd | D17: Threadsol | E17: Delhi | F17: SaaS | G17: 42478 | H17: Seed | I17: N.A | J17: 884.70634 | K17: N.A | L17: =K17 -> N.A | M17: 0 | N17: =M17 -> 0 | O17: Exit Value | P17: 7.335984 | Q17: 0 | R17: 0.0082 | S17: N.A | T17: =V17+U17 -> 7.335985 | U17: 0 | V17: 7.335985 | W17: =T17/P17 -> 1.0000001 | X17: 4.3945313e-08 | Y17: Acquisition by Coates Plc | Z17: =W17 -> 1.0000001 | AA17: Business Development connects, Investor connect, Structuring of business as a SG domiciled entity, finance and compliance, Hiring , structuring of exit transaction | AB17: Catamaran | AC17: Angel Network | AD17: Karthik | AE17: Ashish | AF17: Exited
B18: 15 | C18: Solvy Tech Solutions Pvt. Ltd | D18: Zopper | E18: Delhi | F18: FinTech | G18: 42178 | H18: Seed | I18: N.A | J18: 3374.914 | K18: N.A | L18: =K18 -> N.A | M18: 0 | N18: =M18 -> 0 | O18: Exit Value | P18: 3.9 | Q18: 0 | R18: 0.0012067925 | S18: N.A | T18: =V18+U18 -> 6.067284 | U18: 0 | V18: 6.067284 | W18: =T18/P18 -> 1.5557138 | X18: 0.061516743 | Y18: Sale to Fund 1Y | Z18: =W18 -> 1.5557138 | AA18: Sourcing of follow-on round investors, Finance and compliance support, assistance with M&A transactions , hiring | AB18: Nirvana, Tiger Global | AC18: Alumni network of GPs | AD18: Karthik | AE18: Karthik | AF18: Exited
B19: 16 | C19: WAH Holidays Private Ltd | D19: WeAreHolidays | E19: Delhi | F19: Consumer Services | G19: 42041 | H19: Seed | I19: N.A | J19: 270.17502 | K19: N.A | L19: =K19 -> N.A | M19: 0 | N19: =M19 -> 0 | O19: Written off - residual value received | P19: 5.4 | Q19: 0 | R19: 0.01367339 | S19: N.A | T19: =V19+U19 -> 0.625795 | U19: 0 | V19: 0.625795 | W19: =T19/P19 -> 0.11588796 | X19: NA | Y19: Write-off | Z19: =W19 -> 0.11588796 | AA19: Business Development connects, Finance and compliance support, Board participation, hiring, structuring of follow-on rounds | AB19: Matrix, Mumbai Angels | AC19: Angel Network | AD19: Sanjay | AE19: Karthik | AF19: Written Off
B20: 17 | C20: 21Trends Private Ltd | D20: Voxpop | E20: Mumbai | F20: E-Commerce | G20: 41710 | H20: Seed | I20: N.A | J20: 212.79873 | K20: N.A | L20: =K20 -> N.A | M20: 0 | N20: =M20 -> 0 | O20: Written off - residual value received | P20: 12.2 | Q20: 0 | R20: 0.061400895 | S20: N.A | T20: =V20+U20 -> 0.002696 | U20: 0 | V20: 0.002696 | W20: =T20/P20 -> 0.00022098361 | X20: NA | Y20: Write-off | Z20: =W20 -> 0.00022098361 | AA20: Facilitating collaboration with strategic investor, strategic media arrangement, Finance & compliance support | AC20: Founder network | AD20: Karthik | AE20: Ashish | AF20: Written Off
B21: 18 | C21: Shantani Proteome Analytics Pvt. Ltd | D21: Shantani | E21: Pune | F21: Life Sciences | G21: 41741 | H21: Seed | I21: N.A | J21: 157.54723 | K21: N.A | L21: =K21 -> N.A | M21: 0 | N21: =M21 -> 0 | O21: Written off - residual value received | P21: 3.8 | Q21: 0 | R21: 0.023804062 | S21: N.A | T21: =V21+U21 -> 0.363384 | U21: 0 | V21: 0.363384 | W21: =T21/P21 -> 0.095627368 | X21: NA | Y21: Write-off | Z21: =W21 -> 0.095627368 | AA21: Finance & compliance support | AB21: India Innovation Fund | AC21: Referral by co-investor | AD21: Karthik | AE21: Karthik | AF21: Written Off
B22: 19 | C22: Covacsis Technologies Private Ltd | D22: Covacsis | E22: Mumbai | F22: SaaS | G22: 42093 | H22: Seed | I22: N.A | J22: 389.97214 | K22: N.A | L22: =K22 -> N.A | M22: 0 | N22: =M22 -> 0 | O22: Written off - residual value received | P22: 2.5 | Q22: 0 | R22: 0.0084659668 | S22: N.A | T22: =V22+U22 -> 0 | U22: 0 | V22: 0 | W22: =T22/P22 -> 0 | X22: NA | Y22: Write-off | Z22: =W22 -> 0 | AA22: Finance and compliance support, Business development , debt | AB22: Reliance GenNext, CISCO Ventures | AC22: Founder referral | AD22: Karthik | AE22: Karthik | AF22: Written Off
B23: 20 | C23: Dataemo Technologies Pvt Ltd / Belong Pte Ltd | D23: Belong | E23: Singapore | F23: HRTech | G23: 41912 | H23: Seed | I23: N.A | J23: 177.6 | K23: N.A | L23: =K23 -> N.A | M23: 0 | N23: =M23 -> 0 | O23: Written off - residual value received | P23: 11.2 | Q23: 0 | R23: 0.033783784 | S23: N.A | T23: =V23+U23 -> 0 | U23: 0 | V23: 0 | W23: =T23/P23 -> 0 | X23: NA | Y23: Write-off | Z23: =W23 -> 0 | AA23: Business developement , Board participation, Hiring | AB23: Sequoia, Matrix | AC23: Founder was an ex-team member of a portfolio company | AD23: Karthik | AE23: Karthik | AF23: Written Off
P24: =SUM(P4:P23) -> 224.97682 | Q24: =SUM(Q4:Q23) -> 15.919295 | T24: =SUM(T4:T23) -> 1634.9276 | U24: =SUM(U4:U23) -> 45.116943 | V24: =SUM(V4:V23) -> 1589.8107 | W24: =T24/P24 -> 7.2670935 | X24: 0.34147082
C27: * Indicates that the team member is no longer associated with the firm

Sheet Fund II
B2: # | C2: Company | D2: Business / Brand | E2: Geography | F2: Sector | G2: Date | H2: Stage at Entry | I2: Current Stage | J2: Entry Valuation | K2: Last Round Valuation | L2: Valuation used for Mark to Market | M2: Discount to last round | N2: Effective Valuation for Mark-to-market | O2: Valuation Basis | P2: Total Invested Cost | Q2: Residual Cost | R2: Stake (At Entry) | S2: Stake (Current) | T2: Total Value | U2: Unrealised Value | V2: Realised Value | W2: Gross MOIC | X2: Gross IRR (₹) | Y2: If Exited, Mode of Exit | Z2: GP Exit MOIC | AA2: Value Creation by Fund | AB2: Co-investor(s) | AC2: Sourcing Route | AD2: Deal Source | AE2: Deal Lead | AF2: Status
G3: MM/YY | J3: ₹ Mn | K3: ₹ Mn | L3: ₹ Mn | N3: ₹ Mn | P3: ₹ Mn | Q3: ₹ Mn | R3: % | S3: % | T3: ₹ Mn | U3: ₹ Mn | V3: ₹ Mn | W3: x | X3: %
B4: 1 | C4: Sorting Hat Technology Private Limited | D4: Unacademy | E4: Bengaluru | F4: EdTech | G4: 42338 | H4: Seed | I4: Series H | J4: 325.80706 | K4: 251219.2 | L4: =K4 -> 251219.2 | M4: 0.91281097 | N4: =L4*(1-M4) -> 21903.557 | O4: Valued at $300 Mn basis the M&A offer received | P4: 134.37435 | Q4: =P4 -> 134.37435 | R4: 0.074183976 | S4: 0.0278 | T4: =U4+V4 -> 289.29428 | U4: 289.29428 | V4: 0 | W4: =T4/P4 -> 2.152898 | X4: 0.090212092 | AA4: Investor connect, Finance & compliance support , ESOP , operational finance support , hiring | AB4: General Atlantic, Facebook, Peak XV Partners, Nexus, Elevation Capital, Steadview Capital, Tiger Global, Dragoneer,SoftBank | AC4: Eco-system referral | AD4: Karthik | AE4: Karthik | AF4: Active
B5: 2 | C5: Value Drive Technologies Pvt Ltd | D5: Spinny | E5: Delhi | F5: Consumer Services | G5: 42447 | H5: Seed | I5: Series F | J5: 299.7532 | K5: 96707.808 | L5: =K5 -> 96707.808 | M5: 0.10587068 | N5: =L5*(1-M5) -> 86469.287 | O5: Held at secondary valuation of the last round (Series F - Mar 25) | P5: 91.965892 | Q5: 43.408817 | R5: 0.10006673 | S5: 0.024102379 | T5: =U5+V5 -> 3995.2659 | U5: 2107.7868 | V5: 1887.4791 | W5: =T5/P5 -> 43.442909 | X5: 0.70640911 | Y5: Partial exit - Secondary sale to Accel, Paramark | Z5: =V5/(P5-Q5) -> 38.871351 | AA5: Debt, Strategy, Investor connect, Finance & compliance support | AB5: ADQ, Tiger Global, Accel, Elevation Capital, Kaiser, Avenir, Think Investments, Fundamentum | AC5: Eco-system referral | AD5: Arpit | AE5: Arpit | AF5: Partial Exit
B6: 3 | C6: Dunzo Digital Private Limited | D6: Dunzo | E6: Bengaluru | F6: Consumer Tech | G6: 42223 | H6: Seed | I6: Series F | J6: 159.996 | K6: 60913.135 | L6: 772 | M6: 1 | N6: =L6*(1-M6) -> 0 | O6: Provisioned 100% | P6: 99.780115 | Q6: =P6 -> 99.780115 | R6: 0.14 | S6: 0.0245 | T6: =U6+V6 -> 0 | U6: 0 | V6: 0 | W6: =T6/P6 -> 0 | X6: NA | AA6: Investor connect, Finance & compliance support , Hiring | AB6: Aspada, Google Asia, LightBox, Reliance Retail, LGT Lightstone, LightRock | AC6: LP referral | AD6: Adit* | AE6: Karthik | AF6: Provisioned
B7: 4 | C7: Garagepreneurs Internet Private Limited | D7: Slice | E7: Bengaluru | F7: FinTech | G7: 42275 | H7: Series A1 | I7: CCD - Post Series B1 | J7: 133.3039 | K7: 19454.765 | L7: =K7 -> 19454.765 | M7: 0 | N7: =L7*(1-M7) -> 19454.765 | O7: Held at the CCD round (Post merger) | P7: 94.195658 | Q7: =P7 -> 94.195658 | R7: 0.15003751 | S7: 0.081093355 | T7: =U7+V7 -> 1577.6521 | U7: 1577.6521 | V7: 0 | W7: =T7/P7 -> 16.748672 | X7: 0.36665381 | AA7: Business development connects, Strategy, Investor connect, Compliance support , operational finnace support, business structuring | AB7: Tiger Global, Gunosy, Insight, Advent International | AC7: Events / Outbound | AD7: Adit* | AE7: Ashish | AF7: Active
B8: 5 | C8: Tricog Health Pte Ltd | D8: Tricog | E8: Singapore | F8: HealthTech | G8: 42543 | H8: Series A | I8: Series C | J8: 400.1069 | K8: 7029.5271 | L8: =K8 -> 7029.5271 | M8: 0 | N8: =L8*(1-M8) -> 7029.5271 | O8: Marked at Series C (Jan 23) | P8: 83.512193 | Q8: =P8 -> 83.512193 | R8: 0.125 | S8: 0.076019761 | T8: =U8+V8 -> 570.10782 | U8: 570.10782 | V8: 0 | W8: =T8/P8 -> 6.8266417 | X8: 0.24541058 | AA8: Strategy, Finance support , Investor connect , Structuring of business as a SG domiciled entity, operational finance support | AB8: Athera Venture Partners, UTEC, Sony Innovation Fund, Omron | AC8: Inbound / Events | AD8: Arpit | AE8: Sanjay | AF8: Active
B9: 6 | C9: Smallcase Technologies Private Limited | D9: SmallCase | E9: Bengaluru | F9: FinTech | G9: 42284 | H9: Seed | I9: Series D | J9: 100.006 | K9: 24870.194 | L9: =K9 -> 24870.194 | M9: 0.1793 | N9: =L9*(1-M9) -> 20410.968 | O9: Marked at the secondary valuation of the Series D (pre-money) round (Mar 25) | P9: 111.49582 | Q9: 43.367258 | R9: 0.14 | S9: 0.052254968 | T9: =U9+V9 -> 1744.3478 | U9: 1066.0917 | V9: 678.25615 | W9: =T9/P9 -> 15.644962 | X9: 0.41813425 | Y9: Partial exit - Secondary sale to GP managed vehicle | Z9: =V9/(P9-Q9) -> 9.9555328 | AA9: Fund raise connect, Finance & complaince support, strategy, hiring, operational finance support | AB9: State Street, Faering Capital, Amazon, Premji Invest, Sequoia, DSP Adiko, Beenext, Unitary Fund, Straddle Capital, HDFC | AC9: Founder network | AD9: Rohan* | AE9: Karthik | AF9: Partial Exit
B10: 7 | C10: Carthero Technologies Private Limited | D10: Runnr | E10: Bengaluru | F10: Consumer Services | G10: 42129 | H10: Series A | I10: NA | J10: 190.0063 | K10: NA | L10: 0 | M10: 0 | N10: NA | O10: Exit Value | P10: 132.47772 | R10: 0.08475 | S10: NA | T10: =U10+V10 -> 521.26577 | U10: 0 | V10: 521.26577 | W10: =T10/P10 -> 3.934743 | X10: 0.45268052 | Y10: Acquired by Zomato | Z10: =W10 -> 3.934743 | AA10: Business development connects, strategy, Investor connect, compliance support , ESOP structuring , exit sructuring and execution | AB10: Nexus, Sequoia, Matrix | AC10: Inbound / Events | AD10: Adit* | AE10: AF+KR | AF10: Exited
B11: 8 | C11: Service Lee Technologies Private Limited | D11: Servify | E11: Mumbai | F11: Consumer Tech | G11: 42373 | H11: Seed | I11: Series D3 | J11: 312.52435 | K11: 57770 | L11: 57770 | M11: 0.35 | N11: =L11*(1-M11) -> 37550.5 | O11: 35% discount to last round (Series D3 - August 23) | P11: 103.11818 | Q11: 53.42785 | R11: 0.08 | S11: 0.024620831 | T11: =U11+V11 -> 1990.6569 | U11: 931.79213 | V11: 1058.8648 | W11: =T11/P11 -> 19.304616 | X11: 0.39304954 | Y11: Partial exit - Secondary sale to Oister & GP managed vehicle | Z11: =V11/(P11-Q11) -> 21.309271 | AA11: Investor connect, round support, strategy, M&A, hiring, Finance & compliance support | AB11: Iron Pillar, Beenext, Singularity Investments, IFC | AC11: Founder network | AD11: Karthik | AE11: Karthik | AF11: Partial Exit
B12: 9 | C12: Bombinate Technologies Private Limited | D12: Vokal | E12: Bengaluru | F12: Social Media | G12: 42413 | H12: Seed | I12: NA | J12: 609.65616 | K12: NA | L12: 0 | M12: 0 | N12: =L12*(1-M12) -> 0 | O12: Written off - residual value received | P12: 180.69889 | R12: 0.0379 | S12: NA | T12: =U12+V12 -> 0.004455 | U12: 0 | V12: 0.004455 | W12: =T12/P12 -> 2.4654274e-05 | X12: NA | AA12: Investor connect, hiring | AB12: Tiger Global, Mirae, IIFL Accel, 3one4, Kalaari | AC12: ex-portfolio founder | AD12: Karthik | AE12: Karthik | AF12: Written Off
B13: 10 | C13: Mara Labs Inc. | D13: Locus | E13: USA | F13: Logistics | G13: 42452 | H13: Series A | I13: NA | J13: 866.41629 | K13: NA | L13: 0 | M13: 0 | N13: =L13*(1-M13) -> 0 | O13: Exit Value | P13: 122.59912 | Q13: 122.59912 | R13: 0.04 | S13: NA | T13: =U13+V13 -> 113.08637 | U13: 0 | V13: 113.08637 | W13: =T13/P13 -> 0.92240767 | X13: -0.010044631 | Y13: Acquired by Ingka Group | Z13: =W13 -> 0.92240767 | AA13: Hiring, Investor connect | AB13: Exfinity, Beenext, Falcon Edge, Tiger Global | AC13: Eco-system referral | AD13: Sanjay | AE13: Sanjay | AF13: Active
B14: 11 | C14: Hybrent Inc. | D14: Hybrent | E14: USA | F14: HealthTech | G14: 42608 | H14: Seed | I14: NA | J14: 415.00665 | K14: NA | L14: 0 | M14: 0 | N14: =L14*(1-M14) -> 0 | O14: Exit Value | P14: 92.037188 | R14: 0.1969 | S14: NA | T14: =U14+V14 -> 452.47797 | U14: 0 | V14: 452.47797 | W14: =T14/P14 -> 4.9162515 | X14: 0.41834691 | Y14: Acquired by Procurement Partners | Z14: =W14 -> 4.9162515 | AB14: Montane Ventures | AC14: Eco-system referral | AD14: scout | AE14: Karthik | AF14: Exited
B15: 12 | C15: mPAANI Solutions Private Limited | D15: LoveLocal | E15: Mumbai | F15: Retail-Tech | G15: 42251 | H15: Seed | I15: Pre-Series B | J15: 195.03 | K15: 5157.684 | L15: 0 | M15: 0 | N15: Cost | O15: Cost | P15: 84.89908 | Q15: =P15 -> 84.89908 | R15: 0.1385 | S15: 0.08 | T15: =U15+V15 -> 84.89908 | U15: 84.89908 | V15: 0 | W15: =T15/P15 -> 1 | X15: 2.9802322e-09 | AA15: Business development, Finance & compliance support , Hiring , ESOP, Investor connect | AB15: Vulcan, AVG, IDG,Chiratae, Technology Venture Fund,Saha Fund, Henkel, ACV, Candy Capital | AC15: Eco-system referral | AD15: Sajith | AE15: Karthik | AF15: Active
B16: 13 | C16: Squadrun Inc. | D16: Squad | E16: USA | F16: B2B Services | G16: 42772 | H16: Seed | I16: Series B | J16: 765.65925 | K16: 7545.1152 | L16: 0 | M16: 0 | N16: Cost | O16: Cost | P16: 67.564819 | Q16: =P16 -> 67.564819 | R16: 0.065 | S16: 0.0502 | T16: =U16+V16 -> 67.564819 | U16: 67.564819 | V16: 0 | W16: =T16/P16 -> 1 | X16: 0 | AA16: Business Development connect , hiring | AB16: Chiratae Ventures, Bertelsmann India Investments | AC16: LP referral | AD16: Sanjay | AE16: Karthik | AF16: Active
B17: 14 | C17: True Software Scandinavia AB | D17: Truecaller | E17: Mumbai | F17: FinTech | G17: 42334 | H17: Series A | I17: NA | J17: 1421.307 | K17: NA | L17: 0 | M17: 0 | N17: NA | O17: Exit Value (Includes proceeds from Chillr) | P17: 55.356995 | R17: 0.0422 | S17: NA | T17: =U17+V17 -> 247.01865 | U17: 0 | V17: 247.01865 | W17: =T17/P17 -> 4.4622843 | X17: 0.36432918 | Y17: Acquired by Truecaller in a stock swap deal | Z17: =W17 -> 4.4622843 | AB17: Sequioa,Uniqorn Ventures,MOBME Wireless | AD17: Karthik | AE17: Karthik | AF17: Exited
B18: 15 | C18: Yulu Bikes Pvt Ltd | D18: Yulu | E18: Bengaluru | F18: Urban Mobility | G18: 43214 | H18: CCD | I18: Series B2 | J18: 2127.2964 | K18: 18280 | L18: =K18 -> 18280 | M18: 0.57035125 | N18: =L18*(1-M18) -> 7853.9792 | O18: Estimated Exit Value | P18: 74.82264 | Q18: =P18 -> 74.82264 | R18: 0.0442 | S18: 0.0261 | T18: =U18+V18 -> 194.52041 | U18: 194.52041 | V18: 0 | W18: =T18/P18 -> 2.5997533 | X18: 0.14310011 | AA18: Investor connects for follow-on rounds, Finance & complaince support, Hiring | AB18: Magna International, Bajaj Auto, Akatsuki, 3one4 | AC18: Founder network ( connected through the founder's prior startup) | AD18: Sanjay | AE18: Sanjay | AF18: Active
B19: 16 | C19: Minjar Inc | D19: Minjar | E19: USA | F19: SaaS | G19: 42884 | H19: Seed | I19: NA | J19: 613.29754 | K19: NA | L19: 0 | M19: 0 | N19: NA | O19: Exit Value | P19: 61.531786 | R19: 0.1 | S19: NA | T19: =U19+V19 -> 177.44447 | U19: 0 | V19: 177.44447 | W19: =T19/P19 -> 2.8837855 | X19: 4.8712531 | Y19: Acquired by Nutanix Inc | Z19: =W19 -> 2.8837855 | AA19: Business development connects, strategy, Investor connect, compliance support , exit sructuring and execution | AC19: ex-portfolio founder | AD19: Sanjay | AE19: Sanjay | AF19: Exited
B20: 17 | C20: Healthifyme Pte Ltd | D20: Healthifyme | E20: Singapore | F20: HealthTech | G20: 42454 | H20: Series B | I20: Convert Note | J20: 1397.5615 | K20: 15601.189 | L20: =K20 -> 15601.189 | M20: 1 | N20: =L20*(1-M20) -> 0 | O20: Provisioned 100% | P20: 136.97367 | Q20: =P20 -> 136.97367 | R20: 0.0573 | S20: 0.018472895 | T20: =U20+V20 -> 0 | U20: 0 | V20: 0 | W20: =T20/P20 -> 0 | X20: NA | AA20: Strategy, Finance support , Investor connect , hiring | AB20: Chiratae Ventures, Khosla Ventures, Sistema Asia Fund, HealthQuad, LeapFrog Investments, Athera Venture Partners | AC20: Eco-system referral | AD20: Sanjay | AE20: Karthik | AF20: Provisioned
B21: 18 | C21: Sekhmet Technologies Private Limited | D21: THB | E21: Delhi | F21: HealthTech | G21: 43119 | H21: Seed | I21: Series C | J21: 500.18116 | K21: 6483.9432 | L21: 2105.5397 | M21: 0 | N21: =L21*(1-M21) -> 2105.5397 | O21: Held at Series B round (March 21 - two rounds prior to the last round) | P21: 73.83494 | Q21: =P21 -> 73.83494 | R21: 0.13 | S21: 0.0604 | T21: =U21+V21 -> 169.51512 | U21: 169.51512 | V21: 0 | W21: =T21/P21 -> 2.2958659 | X21: 0.1153734 | AA21: Finance & Compliance support , general counsel, hiring | AB21: Healthquad Fund, Dream Incubator, Filter Capital, Edelweiss Capital, Cornerstone Ventures | AC21: LP referral | AD21: Arpit | AE21: Arpit | AF21: Active
B22: 19 | C22: Health Arx Technologies Private Limited | D22: BeatO | E22: Delhi | F22: HealthTech | G22: 43111 | H22: Pre Series A | I22: Series B | J22: 321.00382 | K22: 7332.7707 | L22: =K22 -> 7332.7707 | M22: 0.5 | N22: =L22*(1-M22) -> 3666.3854 | O22: Marked at 50% discount to the last round (Series B - Nov'22) | P22: 91.663456 | Q22: =P22 -> 91.663456 | R22: 0.125 | S22: 0.071436447 | T22: =U22+V22 -> 261.91354 | U22: 261.91354 | V22: 0 | W22: =T22/P22 -> 2.8573388 | X22: 0.15724209 | AA22: Hiring, strategy and goal setting, market research, business development , Investor connect | AB22: Lightrock India, HealthQuad, Flipkart, W Health Ventures, Orios Venture Partners , Parkview, Leo Capital | AC22: Eco-system referral | AD22: Arpit | AE22: Arpit | AF22: Active
B23: 20 | C23: Mycelium Software Inc. | D23: Rocketium | E23: Bengaluru | F23: SaaS | G23: 43097 | H23: Seed | I23: Series A1 | J23: 111.98781 | K23: 2511.9971 | L23: =K23 -> 2511.9971 | M23: 0.5 | N23: =L23*(1-M23) -> 1255.9986 | O23: Marked at 50% discount to the last round (Series A1 - July 24) | P23: 22.308697 | Q23: =P23 -> 22.308697 | R23: 0.077890134 | S23: 0.048 | T23: =U23+V23 -> 60.415931 | U23: 60.415931 | V23: 0 | W23: =T23/P23 -> 2.7081784 | X23: 0.14584426 | AA23: Business Development connect , general counsel , hiring, Finance & compliance | AB23: Tenacity Ventures, Emergent, Industry Ventures | AC23: through portfolio founder | AD23: Ashish | AE23: Sajith | AF23: Active
B24: 21 | C24: Wynaut Webventures Private Limited | D24: Futwork | E24: Mumbai | F24: B2B Services | G24: 42447 | H24: Seed | I24: Series A | J24: 71.444492 | K24: 709.19243 | L24: 0 | M24: 1 | N24: =L24*(1-M24) -> 0 | O24: Provisioned 100% | P24: 42.754521 | Q24: =P24 -> 42.754521 | R24: 0.07 | S24: 0.1296 | T24: =U24+V24 -> 0 | U24: 0 | V24: 0 | W24: =T24/P24 -> 0 | X24: NA | AA24: Business development connects, Strategy, Finance & Compliance support | AB24: Michael & Susan Dell Foundation, Simile, Artha | AC24: Founder network | AD24: Rohan* | AE24: Sajith | AF24: Provisioned
B25: 22 | C25: Kaleidofin Private Limited | D25: Kaleidofin | E25: Chennai | F25: FinTech | G25: 43181 | H25: Seed | I25: Series B2 | J25: 733.29971 | K25: 7310.2892 | L25: =K25 -> 7310.2892 | M25: 0 | N25: =L25*(1-M25) -> 7310.2892 | O25: Marked up to the last round (Series B2 - August 24) | P25: 95.768592 | Q25: =P25 -> 95.768592 | R25: 0.0698 | S25: 0.04 | T25: =U25+V25 -> 262.00137 | U25: 262.00137 | V25: 0 | W25: =T25/P25 -> 2.7357756 | X25: 0.16188213 | AA25: Business Development connect , general counsel , investor connect, Finance & complaince support, Hiring | AB25: Oikocredit, Omidyar, Michael & Susan Dell Foundation, Bill & Melinda Gates Foundation, Rabo Partnership | AC25: Eco-system referral | AD25: Karthik | AE25: Ashish | AF25: Active
B26: 23 | C26: Stellapps Technologies Private Limited | D26: Stellapps | E26: Bengaluru | F26: AgriTech | G26: 42864 | H26: Series A1 | I26: Series C | J26: 1128.419 | K26: 6245.8286 | L26: =K26 -> 6245.8286 | M26: 0 | N26: =L26*(1-M26) -> 6245.8286 | O26: Marked up to the last round (Series C - September 24) | P26: 104.13215 | Q26: =P26 -> 104.13215 | R26: 0.0487 | S26: 0.0218 | T26: =U26+V26 -> 112.13311 | U26: 112.13311 | V26: 0 | W26: =T26/P26 -> 1.0768347 | X26: 0.0099796325 | AA26: Fund raise connect, hiring , secondary acquistion structuring , Business Development connect | AB26: Bill and Melinda Gates Foundation, IDH Farmfit, Stride Ventures, Blue Ashva Sampada, Omnivore Partners | AC26: VC referral | AD26: Karthik | AE26: Ashish | AF26: Active
B27: 24 | C27: Chatpay Commerce Private Limited | D27: PitStop >>Autoverse | E27: Bengaluru | F27: Consumer Services | G27: 43004 | H27: Bridge | I27: NA | J27: 265.03592 | K27: N.A | L27: 0 | M27: 0 | N27: 0 | O27: Written off - residual value received | P27: 89.185459 | R27: 0.0981 | S27: NA | T27: =U27+V27 -> 0.00052166 | U27: 0 | V27: 0.00052166 | W27: =T27/P27 -> 5.8491598e-06 | X27: NA | Z27: =W27 -> 5.8491598e-06 | AA27: Investor connect, operational finance support , hiring | AB27: Exfinity, Ventureast, Singularity | AC27: ex-portfolio founder | AD27: Sajid Fazalbhoy* | AE27: Arpit | AF27: Written Off
B28: 25 | C28: Iluminar Media Private Limited | D28: LBB | E28: Delhi | F28: Commerce & Consumer Brands | G28: 42993 | H28: Seed | I28: NA | J28: 499.98096 | K28: N.A | L28: N.A | M28: 0 | N28: NA | O28: Written off - residual value received | P28: 124.12731 | R28: 0.0942 | S28: NA | T28: =U28+V28 -> 44.025596 | U28: 0 | V28: 44.025596 | W28: =T28/P28 -> 0.35468097 | X28: -0.64531903 | Z28: =W28 -> 0.35468097 | AA28: Helped recruit CTO (even before deal closure), actively led brainstorming strategy and product roadmap sessions, as LBB sharpened focus from just content discovery to real commerce, investor connects for follow on rounds | AB28: Indian Angel Network,Chirate, Inventus | AC28: VC referral | AD28: Arpit | AE28: Sanjay | AF28: Written Off
B29: 26 | C29: Qyuki Digital Media Private Limited | D29: Qyuki | E29: Bengaluru | F29: Media & Entertainment | G29: 43066 | H29: Seed | I29: Series A1 | J29: 316.66662 | K29: 3359.1587 | L29: =K29 -> 3359.1587 | M29: 1 | N29: =L29*(1-M29) -> 0 | O29: Provisioned 100% | P29: 106.03974 | Q29: =P29 -> 106.03974 | R29: 0.1629 | S29: 0.092 | T29: =U29+V29 -> 0 | U29: 0 | V29: 0 | W29: =T29/P29 -> 0 | X29: NA | AA29: Strategy, Finance support , Investor connect , hiring | AB29: Infoedge, CISCO Ventures,BD Mauritius, LuckLegend, DI | AC29: Eco-system referral | AD29: Karthik | AE29: Ashish | AF29: Provisioned
B30: 27 | C30: Servicemart Technologies Private Limited | D30: iservice | E30: Bengaluru | F30: Consumer Tech | G30: 42613 | H30: Seed | I30: NA | J30: 199.91745 | K30: N.A | L30: NA | M30: 0 | N30: NA | O30: Exit Value | P30: 24.99561 | R30: 0.125 | S30: NA | T30: =U30+V30 -> 0 | U30: 0 | V30: 0 | W30: =T30/P30 -> 0 | X30: 0 | Y30: Acquired by Servify in a stock-swap deal | Z30: =W30 -> 0 | AA30: Strategy, Finance support , Investor connect , M&A, hiring | AC30: Founder network | AD30: Karthik | AE30: Karthik | AF30: Written Off
B31: 28 | C31: Aaidea Solutions Private Limited | D31: Milkbasket | E31: Delhi | F31: Consumer Tech | G31: 42873 | H31: Seed | I31: NA | J31: 273.525 | K31: N.A | L31: NA | M31: 0 | N31: NA | O31: Exit Value | P31: 161.94913 | R31: 0.1005 | S31: NA | T31: =U31+V31 -> 161.84378 | U31: 0 | V31: 161.84378 | W31: =T31/P31 -> 0.99934946 | X31: -0.00065054272 | Y31: Acquired by Reliance | Z31: =W31 -> 0.99934946 | AA31: Investor connect, hiring | AB31: Unilever,Ultimate Lenovo, Mayfield | AC31: Inbound / Events | AD31: Arpit | AE31: Arpit | AF31: Exited
B32: 29 | C32: Zenatix Solutions Private Limited | D32: Zenatix | E32: Delhi | F32: DeepTech | G32: 42273 | H32: Bridge | I32: NA | J32: 202.27448 | K32: N.A | L32: NA | M32: 0 | N32: NA | O32: Exit Value | P32: 52.382275 | R32: 0.10998589 | S32: NA | T32: =U32+V32 -> 52.111469 | U32: 0 | V32: 52.111469 | W32: =T32/P32 -> 0.9948302 | X32: -0.0032642648 | Y32: Acquired by Hero Electronics | Z32: =W32 -> 0.9948302 | AA32: Business development, Investor connect , hiring | AB32: Pi Ventures | AC32: Eco-system referral | AD32: Arpit | AE32: Arpit | AF32: Exited
B33: 30 | C33: Mockbank Learning Private Limited | D33: Mockbank | E33: Mumbai | F33: EdTech | G33: 42212 | H33: Seed | I33: NA | J33: 125.0025 | K33: N.A | L33: NA | M33: 0 | N33: NA | O33: Written off - residual value received | P33: 12.50375 | R33: 0.1 | S33: NA | T33: =U33+V33 -> 7.548178 | U33: 0 | V33: 7.548178 | W33: =T33/P33 -> 0.60367314 | X33: -0.39632686 | Z33: =W33 -> 0.60367314 | AA33: NA | AD33: Arpit | AE33: Arpit | AF33: Written Off
B34: 31 | C34: Codelink Technologies Private Limited | D34: Blaez | E34: Delhi | F34: Customer Services | G34: 42299 | H34: Seed | I34: NA | J34: 118.207 | K34: N.A | L34: NA | M34: 0 | N34: NA | O34: Written off - residual value received | P34: 9.306275 | R34: 0.037069213 | S34: NA | T34: =U34+V34 -> 1.16835 | U34: 0 | V34: 1.16835 | W34: =T34/P34 -> 0.12554432 | X34: -0.87445568 | Z34: =W34 -> 0.12554432 | AA34: NA | AD34: Rohan* | AE34: Rohan* | AF34: Written Off
B35: 32 | C35: Mech Mocha Game Studios Private Limited | D35: MechMocha | E35: Bengaluru | F35: Media & Entertainment | G35: 42291 | H35: Seed | I35: NA | J35: 179.99447 | K35: N.A | L35: NA | M35: 0 | N35: NA | O35: Exit value | P35: 113.77836 | R35: 0.1375 | S35: NA | T35: =U35+V35 -> 0.404234 | U35: 0 | V35: 0.404234 | W35: =T35/P35 -> 0.0035528198 | X35: -0.99644718 | Y35: Acquired by Flipkart | Z35: =W35 -> 0.0035528198 | AA35: Business development connects, strategy, Investor connect, Hiring | AB35: Accel,Shunwei, Akatsuki | AC35: Inbound / Events | AD35: Arpit | AE35: Arpit | AF35: Written Off
B36: 33 | C36: Sitara Digital Ventures Private Limited | D36: The Wedding Brigade | E36: Mumbai | F36: Consumer Services | G36: 42443 | H36: Seed | I36: NA | J36: 156.26829 | K36: N.A | L36: NA | M36: 0 | N36: NA | O36: Written off - residual value received | P36: 78.397951 | R36: 0.16 | S36: NA | T36: =U36+V36 -> 0.03546 | U36: 0 | V36: 0.03546 | W36: =T36/P36 -> 0.00045230774 | X36: NA | Z36: =W36 -> 0.00045230774 | AA36: Business development connects, Strategy, Investor connect, Finance & Compliance support , hiring | AB36: Mountain Pine Capital, LetsVenture Investors | AC36: Inbound / Events | AD36: Sajid Fazalbhoy* | AE36: Sajid Fazalbhoy* | AF36: Written Off
