Workbook
Name CIQWBGuid: "9b8b128a-ea69-4f95-8ab7-4b521b087d2d"
Name IQ_CH: 110000
Name IQ_CQ: 5000
Name IQ_CY: 10000
Name IQ_DAILY: 500000
Name IQ_DNTM: 700000
Name IQ_FH: 100000
Name IQ_FQ: 500
Name IQ_FWD_CY: 10001
Name IQ_FWD_CY1: 10002
Name IQ_FWD_CY2: 10003
Name IQ_FWD_FY: 1001
Name IQ_FWD_FY1: 1002
Name IQ_FWD_FY2: 1003
Name IQ_FWD_Q: 501
Name IQ_FWD_Q1: 502
Name IQ_FWD_Q2: 503
Name IQ_FY: 1000
Name IQ_LATESTK: 1000
Name IQ_LATESTQ: 500
Name IQ_LTM: 2000
Name IQ_LTMMONTH: 120000
Name IQ_MONTH: 15000
Name IQ_MTD: 800000
Name IQ_NAMES_REVISION_DATE_: "04/25/2019 07:38:24"
Name IQ_NTM: 6000
Name IQ_QTD: 750000
Name IQ_TODAY: 0
Name IQ_WEEK: 50000
Name IQ_YTD: 3000
Name IQ_YTDMONTH: 130000

Sheet B2B - Non Repair Inputs
A1: Non- Repair (INR) - Inputs | B1: 43208 | C1: 43238 | D1: 43269 | E1: 43282 | F1: 43313 | G1: 43344 | H1: 43374 | I1: 43405 | J1: 43435 | K1: 43466 | L1: 43497 | M1: 43525 | N1: 43556 | O1: 43586 | P1: 43617 | Q1: 43647 | R1: =Q1+31 -> 43678 | S1: =R1+31 -> 43709 | T1: =S1+31 -> 43740 | U1: =T1+31 -> 43771 | V1: =U1+31 -> 43802 | W1: =V1+31 -> 43833 | X1: =W1+31 -> 43864 | Y1: =X1+31 -> 43895 | ... BS1: =BR1+31 -> 45321 | BT1: =BS1+30 -> 45351 | BU1: =BT1+30 -> 45381 | BV1: =BU1+30 -> 45411 | BW1: =BV1+30 -> 45441 | BX1: =BW1+30 -> 45471 | BY1: =BX1+30 -> 45501 | BZ1: =BY1+30 -> 45531 | CA1: =BZ1+30 -> 45561 | ... EC1: =EB1+30 -> 47181 | ED1: x
A2: Gross Revenue (inc. tax) | B2: 127373162 | C2: 119526214 | D2: 1.3361892e+08 | E2: 1.5572126e+08 | F2: 1.8292117e+08 | G2: 190468885 | H2: 203496304 | I2: 191306750 | J2: 241759536 | K2: 234336044 | L2: 2.3858167e+08 | M2: 208964937 | N2: 2.6952158e+08 | O2: 2.6688728e+08 | P2: 2.8626461e+08 | Q2: 292672912 | R2: 2.4150233e+08 | S2: 214319223 | T2: 181364156 | U2: 220788768 | V2: 2.6449597e+08 | W2: 267334479 | X2: 2.9379328e+08 | Y2: 182610351 | Z2: 0 | AA2: 140900548 | AB2: 146263086 | AC2: 119828870 | AD2: 200268733 | AE2: 206503898 | AF2: 186804306 | AG2: 2.2063889e+08 | AH2: 3.5443276e+08 | AI2: 3.059086e+08 | AJ2: 3.8260216e+08 | AK2: 3.2157717e+08 | AL2: 2.2184714e+08 | AM2: 1.0392815e+08 | AN2: 2.2950755e+08 | AO2: 322690111 | AP2: 3.1847108e+08 | AQ2: 3.0977751e+08 | AR2: 2.7614005e+08 | AS2: 3.141244e+08 | AT2: 4.2050482e+08 | AU2: 3.877668e+08 | AV2: 406585986 | AW2: 367317139 | AX2: 364497378 | AY2: 418830243 | AZ2: =AZ3+AZ4 -> 3.2287098e+08 | BA2: =BA3+BA4 -> 3.5962884e+08 | BB2: =BB3+BB4 -> 3.7669515e+08 | BC2: =BC3+BC4 -> 3.7649862e+08 | BD2: =BD3+BD4 -> 4.2638107e+08 | BE2: =BE3+BE4 -> 4.6466709e+08 | BF2: =BF3+BF4 -> 5.8646851e+08 | BG2: =BG3+BG4 -> 5.2943297e+08 | ... DQ2: =DQ3+DQ4 -> 0 | EC2: =EC3+EC4 -> 0 | ED2: x
A3: Offline | AZ3: 57900213 | BA3: 62484773 | BB3: 63293292 | BC3: 1.1271932e+08 | BD3: 1.0161536e+08 | BE3: 1.2246949e+08 | BF3: 1.4776989e+08 | BG3: 1.1208485e+08 | BH3: 59806800 | BI3: 64466321 | BJ3: 39228577 | BK3: 32647113 | BL3: 33153913 | BM3: 15345796 | BN3: 12681235 | BO3: 18397365 | BP3: 28562914 | BQ3: 51819029 | BR3: 42511549 | BS3: 26524843 | BT3: 18495206 | BU3: 31427878 | BV3: 27850812 | BW3: 22729297 | BX3: 10946710 | BY3: 21263730 | BZ3: 29270284 | CA3: 35801443 | CB3: 25116076 | CC3: 15694579 | CD3: 35993006 | CE3: 54975279 | CF3: 35182058 | CG3: 70684511 | CH3: 57976140 | CI3: 56362233 | CJ3: 25843707 | CK3: 29562162 | CL3: 19353126 | CM3: 16747344 | CN3: 22624143 | CO3: 41629922 | CP3: 72883676 | CQ3: 54851941 | CR3: 38432467 | ED3: x
A4: Online | AZ4: 2.6497076e+08 | BA4: 2.9714407e+08 | BB4: 3.1340186e+08 | BC4: 2.637793e+08 | BD4: 3.247657e+08 | BE4: 3.421976e+08 | BF4: 4.3869863e+08 | BG4: 4.1734813e+08 | BH4: 3.7824561e+08 | BI4: 4.1863154e+08 | BJ4: 4.2592753e+08 | BK4: 4.3511469e+08 | BL4: 3.2300388e+08 | BM4: 3.2850307e+08 | BN4: 3.4456507e+08 | BO4: 3.2209393e+08 | BP4: 2.884787e+08 | BQ4: 3.1590853e+08 | BR4: 2.9801067e+08 | BS4: 2.8335834e+08 | BT4: 3.0843154e+08 | BU4: 2.9969907e+08 | BV4: 3.1798799e+08 | BW4: 3.3608515e+08 | BX4: 3.2954318e+08 | BY4: 3.0327311e+08 | BZ4: 2.8538817e+08 | CA4: 2.4773517e+08 | CB4: 3.0363596e+08 | CC4: 3.1660862e+08 | CD4: 3.3832818e+08 | CE4: 3.6436917e+08 | CF4: 4.4184371e+08 | CG4: 5.2195693e+08 | CH4: 4.5438369e+08 | CI4: 4.5251806e+08 | CJ4: 4.9366874e+08 | CK4: 4.7876586e+08 | CL4: 4.1957962e+08 | CM4: 3.5971942e+08 | CN4: 4.5657266e+08 | CO4: 5.2491022e+08 | CP4: 6.1854909e+08 | CQ4: 6.8487692e+08 | CR4: 6.4630524e+08 | ED4: x
ED5: x
A6: Devices | B6: 32077 | C6: 28685 | D6: 34758 | E6: 39298 | F6: 47222 | G6: 49152 | H6: 52716 | I6: 52798 | J6: 67323 | K6: 62990 | L6: 67278 | M6: 53088 | N6: 72396 | O6: 75630 | P6: 76377 | Q6: 71644 | R6: 63244 | S6: 56263 | T6: 46046 | U6: 53509 | V6: 66574 | W6: 66672 | X6: 82936 | Y6: 53988 | Z6: 0 | AA6: 39616 | AB6: 42186 | AC6: 23110 | AD6: 42469 | AE6: 37673 | AF6: 38371 | AG6: 52692 | AH6: 66087 | AI6: 50483 | AJ6: 69399 | AK6: 58903 | AL6: 39902 | AM6: 20877 | AN6: 46075 | AO6: 67308 | AP6: 70639 | AQ6: 66964 | AR6: 60018 | AS6: 75086 | AT6: 92309 | AU6: 84249 | AV6: 78598 | AW6: 72738 | AX6: 67201 | AY6: 75950 | AZ6: =SUM(AZ7:AZ8) -> 55593 | BA6: =SUM(BA7:BA8) -> 62571 | BB6: =SUM(BB7:BB8) -> 65439 | BC6: =SUM(BC7:BC8) -> 69439 | BD6: =SUM(BD7:BD8) -> 64427 | BE6: =SUM(BE7:BE8) -> 69556 | BF6: =SUM(BF7:BF8) -> 86447 | BG6: =SUM(BG7:BG8) -> 76462 | ... DQ6: =SUM(DQ7:DQ8) -> 0 | EC6: =SUM(EC7:EC8) -> 0 | ED6: x
A7: Offline | AZ7: 9439 | BA7: 10854 | BB7: 10760 | BC7: 21806 | BD7: 13898 | BE7: 17371 | BF7: 20911 | BG7: 15473 | BH7: 10466 | BI7: 13386 | BJ7: 5026 | BK7: 4403 | BL7: 5764 | BM7: 3408 | BN7: 2073 | BO7: 3244 | BP7: 5103 | BQ7: 13036 | BR7: 4139 | BS7: 3210 | BT7: 2867 | BU7: 4926 | BV7: 4229 | BW7: 3319 | BX7: 2009 | BY7: 4449 | BZ7: 4259 | CA7: 4375 | CB7: 2935 | CC7: 2537 | CD7: 7861 | CE7: 12311 | CF7: 5940 | CG7: 10233 | CH7: 8955 | CI7: 9131 | CJ7: 3136 | CK7: 4004 | CL7: 2650 | CM7: 3295 | CN7: 2653 | CO7: 6330 | CP7: 7285 | CQ7: 4480 | CR7: 3629.5641 | ED7: x
A8: Online | AZ8: 46154 | BA8: 51717 | BB8: 54679 | BC8: 47633 | BD8: 50529 | BE8: 52185 | BF8: 65536 | BG8: 60989 | BH8: 51027 | BI8: 57821 | BJ8: 56260 | BK8: 54644 | BL8: 37687 | BM8: 40718 | BN8: 45738 | BO8: 43900 | BP8: 34529 | BQ8: 33684 | BR8: 30780 | BS8: 29203 | BT8: 30576 | BU8: 28090 | BV8: 30573 | BW8: 35826 | BX8: 35853 | BY8: 35328 | BZ8: 31014 | CA8: 27470 | CB8: 30565 | CC8: 33360 | CD8: 37963 | CE8: 38551 | CF8: 40985 | CG8: 48977 | CH8: 43458 | CI8: 45214 | CJ8: 48592 | CK8: 47661 | CL8: 45521 | CM8: 38590 | CN8: 46497 | CO8: 54158 | CP8: 60087 | CQ8: 58857 | CR8: 58229 | ED8: x
ED9: x
A10: Returns (inc. tax) | B10: 0 | C10: 0 | D10: 0 | E10: 0 | F10: 0 | G10: 0 | H10: 0 | I10: 0 | J10: 0 | K10: 0 | L10: 0 | M10: 0 | N10: 73665.555 | O10: 18545.06 | P10: 35350.414 | Q10: 313486.29 | R10: 1159355.2 | S10: 1898626.9 | T10: 1537513.1 | U10: 1643268.5 | V10: 3134468.3 | W10: 3493815.9 | X10: 2214326.7 | Y10: 681691.8 | Z10: 58689 | AA10: 78042.06 | AB10: 302378.05 | AC10: 90474.93 | AD10: 203264.43 | AE10: 1361023.8 | AF10: 2293737.3 | AG10: 2673237.4 | AH10: 2807817 | AI10: 3084430.9 | AJ10: 3797965.8 | AK10: 4332916.3 | AL10: 3505842.3 | AM10: 4420191.5 | AN10: 8957793.6 | AO10: 13662088 | AP10: 16041871 | AQ10: 26276687 | AR10: 33122634 | AS10: 23397431 | AT10: 30706134 | AU10: 32673536 | AV10: 43288241 | AW10: 50451902 | AX10: 49613456 | AY10: 64881764 | AZ10: =AZ11+AZ12 -> 69152023 | BA10: =BA11+BA12 -> 64276477 | BB10: =BB11+BB12 -> 61835594 | BC10: =BC11+BC12 -> 53480848 | BD10: =BD11+BD12 -> 46389583 | BE10: =BE11+BE12 -> 53539111 | BF10: =BF11+BF12 -> 62969264 | BG10: =BG11+BG12 -> 57422683 | ... DQ10: =DQ11+DQ12 -> 0 | EC10: =EC11+EC12 -> 0 | ED10: x
A11: Offline | AZ11: 584761.33 | BA11: 130274.59 | BB11: 163329.98 | BC11: 380127.04 | BD11: 1177382.5 | BE11: 2269684.6 | BF11: 308900.99 | BG11: 249670.93 | BH11: 568887.69 | BI11: 1351326 | BJ11: 489349 | BK11: 596455.25 | BL11: 152981.59 | BM11: 200262.42 | BN11: 27457.577 | BO11: 201581.7 | BP11: 2088827.9 | BQ11: 270666.24 | BR11: 88826.571 | BS11: 720660.15 | BT11: 1462117.2 | BU11: 1052057 | BV11: 645068.35 | BW11: 639875.17 | BX11: 851158.77 | BY11: 95498.433 | BZ11: 100441.8 | CA11: 86477.185 | CB11: 313479.17 | CC11: 280926.05 | CD11: 185949.37 | CE11: 12510.888 | CF11: 62892.962 | CG11: 90180.167 | CH11: 147495.14 | CI11: 1251985.5 | CJ11: 55430.529 | CK11: 246236.78 | CL11: 54944.39 | CM11: 93690.25 | CN11: 29481.83 | CO11: 111605.68 | CP11: 311799.45 | CQ11: 120490.87 | CR11: 29857.06 | ED11: x
A12: Online | AZ12: 68567261 | BA12: 64146203 | BB12: 61672264 | BC12: 53100721 | BD12: 45212201 | BE12: 51269427 | BF12: 62660363 | BG12: 57173013 | BH12: 57521228 | BI12: 61272930 | BJ12: 76047181 | BK12: 72098825 | BL12: 55542143 | BM12: 59960809 | BN12: 56538940 | BO12: 50706878 | BP12: 42722467 | BQ12: 33017650 | BR12: 39291726 | BS12: 37875847 | BT12: 40077373 | BU12: 34575290 | BV12: 38382767 | BW12: 40540331 | BX12: 36969260 | BY12: 38326106 | BZ12: 38440252 | CA12: 41192892 | CB12: 38187234 | CC12: 35123003 | CD12: 38377281 | CE12: 34152064 | CF12: 31020347 | CG12: 38758008 | CH12: 42143225 | CI12: 41219534 | CJ12: 59098386 | CK12: 46927371 | CL12: 50189998 | CM12: 40320148 | CN12: 43616763 | CO12: 43585970 | CP12: 57750700 | CQ12: 58166177 | CR12: 62582269 | ED12: x
ED13: x
A14: Devices | B14: 0 | C14: 0 | D14: 0 | E14: 0 | F14: 0 | G14: 0 | H14: 0 | I14: 0 | J14: 0 | K14: 0 | L14: 0 | M14: 0 | N14: 9 | O14: 1 | P14: 4 | Q14: 31 | R14: 137 | S14: 193 | T14: 159 | U14: 148 | V14: 326 | W14: 451 | X14: 337 | Y14: 109 | Z14: 9 | AA14: 1 | AB14: 42 | AC14: 9 | AD14: 41 | AE14: 163 | AF14: 338 | AG14: 440 | AH14: 464 | AI14: 386 | AJ14: 487 | AK14: 544 | AL14: 529 | AM14: 751 | AN14: 1454 | AO14: 2406 | AP14: 3126 | AQ14: 4565 | AR14: 5997 | AS14: 4301 | AT14: 5405 | AU14: 5899 | AV14: 7326 | AW14: 8324 | AX14: 8454 | AY14: 11659 | AZ14: =SUM(AZ15:AZ16) -> 12670 | BA14: =SUM(BA15:BA16) -> 9847 | BB14: =SUM(BB15:BB16) -> 9688 | BC14: =SUM(BC15:BC16) -> 8687 | BD14: =SUM(BD15:BD16) -> 8023 | BE14: =SUM(BE15:BE16) -> 8041 | BF14: =SUM(BF15:BF16) -> 8690 | BG14: =SUM(BG15:BG16) -> 7618 | ... DQ14: =SUM(DQ15:DQ16) -> 0 | EC14: =SUM(EC15:EC16) -> 0 | ED14: x
A15: Offline | AZ15: 98 | BA15: 18 | BB15: 19 | BC15: 90 | BD15: 235 | BE15: 236 | BF15: 39 | BG15: 18 | BH15: 44 | BI15: 301 | BJ15: 33 | BK15: 36 | BL15: 13 | BM15: 11 | BN15: 3 | BO15: 16 | BP15: 101 | BQ15: 15 | BR15: 6 | BS15: 37 | BT15: 65 | BU15: 53 | BV15: 32 | BW15: 26 | BX15: 47 | BY15: 7 | BZ15: 5 | CA15: 4 | CB15: 20 | CC15: 19 | CD15: 12 | CE15: 1 | CF15: 4 | CG15: 5 | CH15: 7 | CI15: 38 | CJ15: 5 | CK15: 11 | CL15: 3 | CM15: 7 | CN15: 2 | CO15: 15 | CP15: 20 | CQ15: 5 | CR15: 2 | ED15: x
A16: Online | AZ16: 12572 | BA16: 9829 | BB16: 9669 | BC16: 8597 | BD16: 7788 | BE16: 7805 | BF16: 8651 | BG16: 7600 | BH16: 7097 | BI16: 7443 | BJ16: 9147 | BK16: 8142 | BL16: 6160 | BM16: 6267 | BN16: 6524 | BO16: 5654 | BP16: 4701 | BQ16: 3420 | BR16: 3691 | BS16: 3335 | BT16: 3361 | BU16: 3021 | BV16: 3318 | BW16: 3853 | BX16: 3974 | BY16: 4020 | BZ16: 3975 | CA16: 4193 | CB16: 3866 | CC16: 3564 | CD16: 3940 | CE16: 3084 | CF16: 2578 | CG16: 3041 | CH16: 3414 | CI16: 3184 | CJ16: 4800.6316 | CK16: 3809 | CL16: 3994 | CM16: 3306 | CN16: 3861 | CO16: 3927 | CP16: 4814 | CQ16: 4246 | CR16: 4440 | ED16: x
A18: Return% | B18: =B14/B6 -> 0 | C18: =C14/C6 -> 0 | D18: =D14/D6 -> 0 | E18: =E14/E6 -> 0 | F18: =F14/F6 -> 0 | G18: =G14/G6 -> 0 | H18: =H14/H6 -> 0 | I18: =I14/I6 -> 0 | ... DQ18: =DQ14/DQ6 -> #DIV/0! | EC18: =EC14/EC6 -> #DIV/0! | ED18: x
ED19: x
A20: #RTO | ED20: x
A21: #Quality return | ED21: x
ED22: x
A23: Revenue Pre Tax (after returns) | B23: =B2-B10 -> 127373162 | C23: =C2-C10 -> 119526214 | D23: =D2-D10 -> 1.3361892e+08 | E23: =E2-E10 -> 1.5572126e+08 | F23: =F2-F10 -> 1.8292117e+08 | G23: =G2-G10 -> 190468885 | H23: =H2-H10 -> 203496304 | I23: =I2-I10 -> 191306750 | ... DQ23: =DQ2-DQ10 -> 0 | ED23: x
A24: Offline | AZ24: =AZ3-AZ11 -> 57315452 | BA24: =BA3-BA11 -> 62354498 | BB24: =BB3-BB11 -> 63129962 | BC24: =BC3-BC11 -> 1.123392e+08 | BD24: =BD3-BD11 -> 1.0043798e+08 | BE24: =BE3-BE11 -> 1.2019981e+08 | BF24: =BF3-BF11 -> 1.4746099e+08 | BG24: =BG3-BG11 -> 1.1183517e+08 | ... DQ24: =DQ3-DQ11 -> 0 | ED24: x
A25: Online | AZ25: =AZ4-AZ12 -> 1.964035e+08 | BA25: =BA4-BA12 -> 2.3299787e+08 | BB25: =BB4-BB12 -> 2.5172959e+08 | BC25: =BC4-BC12 -> 2.1067857e+08 | BD25: =BD4-BD12 -> 2.795535e+08 | BE25: =BE4-BE12 -> 2.9092817e+08 | BF25: =BF4-BF12 -> 3.7603826e+08 | BG25: =BG4-BG12 -> 3.6017512e+08 | ... DQ25: =DQ4-DQ12 -> 0 | ED25: x
ED26: x
A27: Tax | B27: 1571885 | C27: 1933226.9 | D27: 2144810.8 | E27: 2670744.5 | F27: 3520739.2 | G27: 3375803 | H27: 2640496 | I27: 3233060 | J27: 3701309 | K27: 2919247 | L27: 2007686 | M27: 2008229 | N27: 2074638.9 | O27: 2149447 | P27: 2794451.4 | Q27: 3291671.1 | R27: 3107953 | S27: 2375814.6 | T27: 2358981.6 | U27: 2789918.8 | V27: 2858485.1 | W27: 2908758.5 | X27: 3984937.7 | Y27: 2321371.6 | Z27: -1030.5643 | AA27: 3900614 | AB27: 3270039.7 | AC27: 2663850.8 | AD27: 4690032.1 | AE27: 4140394.6 | AF27: 3479215.8 | AG27: 4885138.6 | AH27: 5677808.9 | AI27: 4311081.9 | AJ27: 5245946.8 | AK27: 3879587.6 | AL27: 2963722 | AM27: 2026289 | AN27: 4833429.7 | AO27: 6484924.1 | AP27: 6968696.5 | AQ27: 6104232 | AR27: 5760470 | AS27: 4515277 | AT27: 5958902.2 | AU27: 5855167 | AV27: 5581986 | AW27: 5571264.4 | AX27: 4708314 | AY27: 6279353 | AZ27: =SUM(AZ28:AZ29) -> 4093538 | BA27: =SUM(BA28:BA29) -> 5519187.2 | BB27: =SUM(BB28:BB29) -> 5516764.6 | BC27: =SUM(BC28:BC29) -> 4791504.7 | BD27: =SUM(BD28:BD29) -> 6953816.6 | BE27: =SUM(BE28:BE29) -> 7179089.4 | BF27: =SUM(BF28:BF29) -> 10406552 | BG27: =SUM(BG28:BG29) -> 9057356 | ... DQ27: =SUM(DQ28:DQ29) -> 0 | ED27: x
A28: Offline | AZ28: 960772.07 | BA28: 1180105.8 | BB28: 1161482.7 | BC28: 1878845 | BD28: 1629749.6 | BE28: 2117305.1 | BF28: 1382356.2 | BG28: 779964.99 | BH28: 596616.3 | BI28: 653500.05 | BJ28: 475368.76 | BK28: 198593.3 | BL28: 139299.02 | BM28: 137603.5 | BN28: 146922.95 | BO28: 179555.22 | BP28: 263183.63 | BQ28: 210872.93 | BR28: 198148.78 | BS28: 102098.82 | BT28: 126079.52 | BU28: 193607.99 | BV28: 266230.94 | BW28: 104389.34 | BX28: 83506.939 | BY28: 171907.84 | BZ28: 119979.73 | CA28: 117804.4 | CB28: 73628.41 | CC28: 115456.84 | CD28: 108032.84 | CE28: 267402.99 | CF28: 403646.39 | CG28: 411033.32 | CH28: 222232.41 | CI28: 339234.07 | CJ28: 218144.36 | CK28: 418634.84 | CL28: 236448.76 | CM28: 197511.29 | CN28: 279793.06 | CO28: 444109.4 | CP28: 618311.15 | CQ28: 522041.17 | CR28: 550125.01 | ED28: x
A29: Online | AZ29: 3132765.9 | BA29: 4339081.4 | BB29: 4355281.9 | BC29: 2912659.7 | BD29: 5324067 | BE29: 5061784.3 | BF29: 9024195.8 | BG29: 8277391.1 | BH29: 6656547.8 | BI29: 7729670.7 | BJ29: 8363230.5 | BK29: 7156313.9 | BL29: 7022111.1 | BM29: 7815907.2 | BN29: 8136675.3 | BO29: 6020908 | BP29: 6350776.3 | BQ29: 7198305.9 | BR29: 5551900.4 | BS29: 5584592.1 | BT29: 7544686.7 | BU29: 7830571.5 | BV29: 8261600.7 | BW29: 8732766.7 | BX29: 8098787.9 | BY29: 7351110.3 | BZ29: 6390671.9 | CA29: 5169085 | CB29: 7376989.1 | CC29: 8396610 | CD29: 7479113.1 | CE29: 8702327.1 | CF29: 11041332 | CG29: 11266326 | CH29: 10768936 | CI29: 13780580 | CJ29: 16283897 | CK29: 12669575 | CL29: 11624734 | CM29: 11375144 | CN29: 13815388 | CO29: 15375280 | CP29: 17711509 | CQ29: 20663540 | CR29: 20888366 | ED29: x
A30: Tax% | ED30: x
ED31: x
A32: Revenue Post Tax (after returns) | B32: =B23-B27 -> 125801277 | C32: =C23-C27 -> 1.1759299e+08 | D32: =D23-D27 -> 1.3147411e+08 | E32: =E23-E27 -> 1.5305052e+08 | F32: =F23-F27 -> 1.7940043e+08 | G32: =G23-G27 -> 187093082 | H32: =H23-H27 -> 200855808 | I32: =I23-I27 -> 188073690 | ... DQ32: =DQ23-DQ27 -> 0 | ED32: x
A33: Offline | AZ33: =AZ24-AZ28 -> 56354680 | BA33: =BA24-BA28 -> 61174392 | BB33: =BB24-BB28 -> 61968479 | BC33: =BC24-BC28 -> 1.1046035e+08 | BD33: =BD24-BD28 -> 98808232 | BE33: =BE24-BE28 -> 1.1808251e+08 | BF33: =BF24-BF28 -> 1.4607863e+08 | BG33: =BG24-BG28 -> 1.1105521e+08 | ... DQ33: =DQ24-DQ28 -> 0 | ED33: x
A34: Online | AZ34: =AZ25-AZ29 -> 1.9327073e+08 | BA34: =BA25-BA29 -> 2.2865879e+08 | BB34: =BB25-BB29 -> 2.4737431e+08 | BC34: =BC25-BC29 -> 2.0776591e+08 | BD34: =BD25-BD29 -> 2.7422944e+08 | BE34: =BE25-BE29 -> 2.8586639e+08 | BF34: =BF25-BF29 -> 3.6701407e+08 | BG34: =BG25-BG29 -> 3.5189773e+08 | ... DQ34: =DQ25-DQ29 -> 0 | ED34: x
ED35: x
A36: Devices | B36: =B6-B14 -> 32077 | C36: =C6-C14 -> 28685 | D36: =D6-D14 -> 34758 | E36: =E6-E14 -> 39298 | F36: =F6-F14 -> 47222 | G36: =G6-G14 -> 49152 | H36: =H6-H14 -> 52716 | I36: =I6-I14 -> 52798 | ... DQ36: =DQ6-DQ14 -> 0 | ED36: x
A37: Offline | AZ37: =AZ7-AZ15 -> 9341 | BA37: =BA7-BA15 -> 10836 | BB37: =BB7-BB15 -> 10741 | BC37: =BC7-BC15 -> 21716 | BD37: =BD7-BD15 -> 13663 | BE37: =BE7-BE15 -> 17135 | BF37: =BF7-BF15 -> 20872 | BG37: =BG7-BG15 -> 15455 | ... DQ37: =DQ7-DQ15 -> 0 | ED37: x
A38: Online | AZ38: =AZ8-AZ16 -> 33582 | BA38: =BA8-BA16 -> 41888 | BB38: =BB8-BB16 -> 45010 | BC38: =BC8-BC16 -> 39036 | BD38: =BD8-BD16 -> 42741 | BE38: =BE8-BE16 -> 44380 | BF38: =BF8-BF16 -> 56885 | BG38: =BG8-BG16 -> 53389 | ... DQ38: =DQ8-DQ16 -> 0 | ED38: x
A39: ASP | ED39: x
ED40: x
ED41: x
...

Sheet Summary Dashboard
C4: FY25 | D4: FY26 | E4: FY27 | F4: FY28
B5: Revenue
B6: B2B - Non Repair | C6: ='B2B- Non Repair'!FG32 -> 3.9389294e+09 | D6: ='B2B- Non Repair'!FH32 -> 5.8927142e+09 | E6: ='B2B- Non Repair'!FI32 -> 7.5558035e+09 | F6: ='B2B- Non Repair'!FJ32 -> 9.4447544e+09
B16: Gross Margin %
B17: B2B - Non Repair | C17: ='B2B- Non Repair'!FG70 -> 0.06359302 | D17: ='B2B- Non Repair'!FH70 -> 0.06863504 | E17: ='B2B- Non Repair'!FI70 -> 0.066490362 | F17: ='B2B- Non Repair'!FJ70 -> 0.075282652

Sheet P&L - Inputs
A1: Inputs Sheet | B1: 43208 | C1: 43238 | D1: 43269 | E1: 43282 | F1: 43313 | G1: 43344 | H1: 43374 | I1: 43405 | J1: 43435 | K1: 43466 | L1: 43497 | M1: 43525 | N1: 43556 | O1: 43586 | P1: 43617 | Q1: 43647 | R1: =Q1+31 -> 43678 | S1: =R1+31 -> 43709 | T1: =S1+31 -> 43740 | U1: =T1+31 -> 43771 | V1: =U1+31 -> 43802 | W1: =V1+31 -> 43833 | X1: =W1+31 -> 43864 | Y1: =X1+31 -> 43895 | ... BS1: =BR1+31 -> 45321 | BT1: =BS1+30 -> 45351 | BU1: =BT1+30 -> 45381 | BV1: =BU1+30 -> 45411 | BW1: =BV1+30 -> 45441 | BX1: =BW1+30 -> 45471 | BY1: =BX1+30 -> 45501 | BZ1: =BY1+30 -> 45531 | CA1: =BZ1+30 -> 45561 | ... EC1: =EB1+30 -> 47181 | ED1: x
ED2: x
A3: B2B - Non Repair | ED3: x
A4: Transaction growth % | N4: =N12/B12-1 -> 1.2569442 | O4: =O12/C12-1 -> 1.6365696 | P4: =P12/D12-1 -> 1.1973934 | Q4: =Q12/E12-1 -> 0.82309532 | R4: =R12/F12-1 -> 0.33929101 | S4: =S12/G12-1 -> 0.14467367 | T4: =T12/H12-1 -> -0.12652705 | U4: =U12/I12-1 -> 0.013466419 | ... CS4: =CS12/CG12-1 -> 0.006795688 | CT4: 0.33 | CU4: =CT4 -> 0.33 | CV4: =CU4 -> 0.33 | CW4: =CV4 -> 0.33 | CX4: =CW4 -> 0.33 | CY4: =CX4 -> 0.33 | CZ4: =CY4 -> 0.33 | DA4: =CZ4 -> 0.33 | DB4: =DA4 -> 0.33 | ... DE4: =DD4 -> 0.33 | DF4: 0.25 | DG4: =DF4 -> 0.25 | DH4: =DG4 -> 0.25 | DI4: =DH4 -> 0.25 | DJ4: =DI4 -> 0.25 | DK4: =DJ4 -> 0.25 | DL4: =DK4 -> 0.25 | DM4: =DL4 -> 0.25 | DN4: =DM4 -> 0.25 | ... DQ4: =DP4 -> 0.25 | DR4: 0.2 | DS4: =DR4 -> 0.2 | DT4: =DS4 -> 0.2 | DU4: =DT4 -> 0.2 | DV4: =DU4 -> 0.2 | DW4: =DV4 -> 0.2 | DX4: =DW4 -> 0.2 | DY4: =DX4 -> 0.2 | DZ4: =DY4 -> 0.2 | ... EC4: =EB4 -> 0.2 | ED4: x
ED5: x
A6: GMV | ED6: x
A7: Gross GMV | B7: 127373162 | C7: 119525214 | D7: 1.3361892e+08 | E7: 1.5572126e+08 | F7: 1.8292117e+08 | G7: 190468885 | H7: 203496304 | I7: 191306750 | J7: 241759536 | K7: 234336044 | L7: 2.3858167e+08 | M7: 208964937 | N7: 2.6952158e+08 | O7: 2.6688728e+08 | P7: 2.8626461e+08 | Q7: 292672912 | R7: 2.4150233e+08 | S7: 214319223 | T7: 181364156 | U7: 220788768 | V7: 2.5449597e+08 | W7: 257334479 | X7: 2.9379328e+08 | Y7: 182610351 | Z7: 0 | AA7: 140900548 | AB7: 146263086 | AC7: 119828870 | AD7: 200258733 | AE7: 206503898 | AF7: 186804306 | AG7: 2.2063889e+08 | AH7: 3.5443276e+08 | AI7: 3.059086e+08 | AJ7: 3.8260216e+08 | AK7: 3.2157717e+08 | AL7: 2.2184714e+08 | AM7: 1.0392815e+08 | AN7: 2.2950755e+08 | AO7: 322690111 | AP7: 3.1847108e+08 | AQ7: 3.0977751e+08 | AR7: 2.7614005e+08 | AS7: 3.141244e+08 | AT7: 4.2050482e+08 | AU7: 3.877668e+08 | AV7: 406585986 | AW7: 367317139 | AX7: 364497378 | AY7: 418830243 | AZ7: =AZ8+AZ9 -> 3.2287098e+08 | BA7: =BA8+BA9 -> 3.5962884e+08 | BB7: =BB8+BB9 -> 3.7669515e+08 | BC7: =BC8+BC9 -> 3.7649862e+08 | BD7: =BD8+BD9 -> 4.2638107e+08 | BE7: =BE8+BE9 -> 4.6466709e+08 | BF7: =BF8+BF9 -> 5.8646851e+08 | BG7: =BG8+BG9 -> 5.2943297e+08 | ... CS7: =CS8+CS9 -> 6.7110911e+08 | CT7: =CT12*CT18 -> 6.910943e+08 | CU7: =CU12*CU18 -> 7.1656878e+08 | CV7: =CV12*CV18 -> 6.8206219e+08 | CW7: =CW12*CW18 -> 6.812315e+08 | CX7: =CX12*CX18 -> 6.3516119e+08 | CY7: =CY12*CY18 -> 5.5227681e+08 | CZ7: =CZ12*CZ18 -> 6.4806984e+08 | DA7: =DA12*DA18 -> 7.9756762e+08 | ... EC7: =EC12*EC18 -> 1.179033e+09 | ED7: x
A8: Offline | AZ8: 57900213 | BA8: 62484773 | BB8: 63293292 | BC8: 1.1271932e+08 | BD8: 1.0161536e+08 | BE8: 1.2246949e+08 | BF8: 1.4776989e+08 | BG8: 1.1208485e+08 | BH8: 59806800 | BI8: 64466321 | BJ8: 39228577 | BK8: 32647113 | BL8: 33153913 | BM8: 15345796 | BN8: 12681235 | BO8: 18397365 | BP8: 28562914 | BQ8: 51819029 | BR8: 42511549 | BS8: 26524843 | BT8: 18495206 | BU8: 31427878 | BV8: 27850812 | BW8: 22729297 | BX8: 10946710 | BY8: 21263730 | BZ8: 29270284 | CA8: 35801443 | CB8: 25116076 | CC8: 15694579 | CD8: 35993006 | CE8: 54975279 | CF8: 35182058 | CG8: 70684511 | CH8: 57976140 | CI8: 56362233 | CJ8: 25843707 | CK8: 29562162 | CL8: 19353126 | CM8: 16747344 | CN8: 22624143 | CO8: 41629922 | CP8: 72883676 | CQ8: 54851941 | CR8: 38432467 | CS8: 26174248 | CT8: =CS8/CS$7*CT$7 -> 26953699 | CU8: =CT8/CT$7*CU$7 -> 27947242 | CV8: =CU8/CU$7*CV$7 -> 26601434 | CW8: =CV8/CV$7*CW$7 -> 26569036 | CX8: =CW8/CW$7*CX$7 -> 24772225 | CY8: =CX8/CX$7*CY$7 -> 21539612 | CZ8: =CY8/CY$7*CZ$7 -> 25275682 | DA8: =CZ8/CZ$7*DA$7 -> 31106316 | ... EC8: =EB8/EB$7*EC$7 -> 45984030 | ED8: x
A9: Online | AZ9: 2.6497076e+08 | BA9: 2.9714407e+08 | BB9: 3.1340186e+08 | BC9: 2.637793e+08 | BD9: 3.247657e+08 | BE9: 3.421976e+08 | BF9: 4.3869863e+08 | BG9: 4.1734813e+08 | BH9: 3.7824561e+08 | BI9: 4.1863154e+08 | BJ9: 4.2592753e+08 | BK9: 4.3511469e+08 | BL9: 3.2300388e+08 | BM9: 3.2850307e+08 | BN9: 3.4456507e+08 | BO9: 3.2209393e+08 | BP9: 2.884787e+08 | BQ9: 3.1590853e+08 | BR9: 2.9801067e+08 | BS9: 2.8335834e+08 | BT9: 3.0843154e+08 | BU9: 2.9969907e+08 | BV9: 3.1798799e+08 | BW9: 3.3608515e+08 | BX9: 3.2954318e+08 | BY9: 3.0327311e+08 | BZ9: 2.8538817e+08 | CA9: 2.4773517e+08 | CB9: 3.0363596e+08 | CC9: 3.1660862e+08 | CD9: 3.3832818e+08 | CE9: 3.6436917e+08 | CF9: 4.4184371e+08 | CG9: 5.2195693e+08 | CH9: 4.5438369e+08 | CI9: 4.5251806e+08 | CJ9: 4.9366874e+08 | CK9: 4.7876586e+08 | CL9: 4.1957962e+08 | CM9: 3.5971942e+08 | CN9: 4.5657266e+08 | CO9: 5.2491022e+08 | CP9: 6.1854909e+08 | CQ9: 6.8487692e+08 | CR9: 6.4630524e+08 | CS9: 6.4493486e+08 | CT9: =CS9/CS$7*CT$7 -> 6.641406e+08 | CU9: =CT9/CT$7*CU$7 -> 6.8862154e+08 | CV9: =CU9/CU$7*CV$7 -> 6.5546076e+08 | CW9: =CV9/CV$7*CW$7 -> 6.5466247e+08 | CX9: =CW9/CW$7*CX$7 -> 6.1038896e+08 | CY9: =CX9/CX$7*CY$7 -> 5.307372e+08 | CZ9: =CY9/CY$7*CZ$7 -> 6.2279416e+08 | DA9: =CZ9/CZ$7*DA$7 -> 7.664613e+08 | ... EC9: =EB9/EB$7*EC$7 -> 1.133049e+09 | ED9: x
ED10: x
A11: Devices | ED11: x
A12: Devices sold | B12: 32077 | C12: 28685 | D12: 34758 | E12: 39298 | F12: 47222 | G12: 49152 | H12: 52716 | I12: 52798 | J12: 67323 | K12: 62990 | L12: 67278 | M12: 53088 | N12: 72396 | O12: 75630 | P12: 76377 | Q12: 71644 | R12: 63244 | S12: 56263 | T12: 46046 | U12: 53509 | V12: 66574 | W12: 66672 | X12: 82936 | Y12: 53988 | Z12: 0 | AA12: 39616 | AB12: 42186 | AC12: 23110 | AD12: 42469 | AE12: 37673 | AF12: 38371 | AG12: 52592 | AH12: 66087 | AI12: 50483 | AJ12: 69399 | AK12: 58903 | AL12: 39902 | AM12: 20877 | AN12: 46075 | AO12: 67308 | AP12: 70639 | AQ12: 66964 | AR12: 60018 | AS12: 75086 | AT12: 92309 | AU12: 84249 | AV12: 78598 | AW12: 72738 | AX12: 67201 | AY12: 75950 | AZ12: =AZ13+AZ14 -> 55593 | BA12: =BA13+BA14 -> 62571 | BB12: =BB13+BB14 -> 65439 | BC12: =BC13+BC14 -> 69439 | BD12: =BD13+BD14 -> 64427 | BE12: =BE13+BE14 -> 69556 | BF12: =BF13+BF14 -> 86447 | BG12: =BG13+BG14 -> 76462 | ... EC12: =EC13+EC14 -> 118926.68 | ED12: x
A13: # Offline sales | AZ13: 9439 | BA13: 10854 | BB13: 10760 | BC13: 21806 | BD13: 13898 | BE13: 17371 | BF13: 20911 | BG13: 15473 | BH13: 10466 | BI13: 13386 | BJ13: 5025 | BK13: 4403 | BL13: 5764 | BM13: 3408 | BN13: 2073 | BO13: 3244 | BP13: 5103 | BQ13: 13036 | BR13: 4139 | BS13: 3210 | BT13: 2867 | BU13: 4925 | BV13: 4229 | BW13: 3319 | BX13: 2009 | BY13: 4449 | BZ13: 4259 | CA13: 4375 | CB13: 2935 | CC13: 2537 | CD13: 7861 | CE13: 12311 | CF13: 5940 | CG13: 10233 | CH13: 8955 | CI13: 9131 | CJ13: 3136 | CK13: 4004 | CL13: 2650 | CM13: 3295 | CN13: 2653 | CO13: 6330 | CP13: 7285 | CQ13: 4480 | CR13: 3629.5641 | CS13: 2417.3727 | CT13: =CH13*(1+CT4) -> 11910.15 | CU13: =CI13*(1+CU4) -> 12144.23 | CV13: =CJ13*(1+CV4) -> 4170.88 | CW13: =CK13*(1+CW4) -> 5325.32 | CX13: =CL13*(1+CX4) -> 3524.5 | CY13: =CM13*(1+CY4) -> 4382.35 | CZ13: =CN13*(1+CZ4) -> 3528.49 | DA13: =CO13*(1+DA4) -> 8418.9 | ... EC13: =DQ13*(1+EC4) -> 4822.6585 | ED13: x
A14: # Online sales | AZ14: 46154 | BA14: 51717 | BB14: 54679 | BC14: 47633 | BD14: 50529 | BE14: 52185 | BF14: 65536 | BG14: 60989 | BH14: 51027 | BI14: 57821 | BJ14: 56250 | BK14: 54644 | BL14: 37687 | BM14: 40718 | BN14: 45738 | BO14: 43900 | BP14: 34529 | BQ14: 33684 | BR14: 30780 | BS14: 29203 | BT14: 30576 | BU14: 28090 | BV14: 30573 | BW14: 35825 | BX14: 35853 | BY14: 35328 | BZ14: 31014 | CA14: 27470 | CB14: 30565 | CC14: 33360 | CD14: 37963 | CE14: 38551 | CF14: 40985 | CG14: 48977 | CH14: 43458 | CI14: 45214 | CJ14: 48592 | CK14: 47661 | CL14: 45521 | CM14: 38590 | CN14: 46497 | CO14: 54158 | CP14: 60087 | CQ14: 58857 | CR14: 58229 | CS14: 57195 | CT14: =CH14*(1+CT4) -> 57799.14 | CU14: =CI14*(1+CU4) -> 60134.62 | CV14: =CJ14*(1+CV4) -> 64627.36 | CW14: =CK14*(1+CW4) -> 63389.13 | CX14: =CL14*(1+CX4) -> 60542.93 | CY14: =CM14*(1+CY4) -> 51324.7 | CZ14: =CN14*(1+CZ4) -> 61841.01 | DA14: =CO14*(1+DA4) -> 72030.14 | ... EC14: =DQ14*(1+EC4) -> 114104.02 | ED14: x
A15: Offline % | AZ15: =AZ13/AZ$12 -> 0.16978756 | BA15: =BA13/BA$12 -> 0.17346694 | BB15: =BB13/BB$12 -> 0.16442794 | BC15: =BC13/BC$12 -> 0.31403102 | BD15: =BD13/BD$12 -> 0.21571701 | BE15: =BE13/BE$12 -> 0.24974122 | BF15: =BF13/BF$12 -> 0.24189388 | BG15: =BG13/BG$12 -> 0.20236196 | ... CS15: =CS13/CS$12 -> 0.040551526 | CT15: =CT13/CT12 -> 0.17085456 | CU15: =CU13/CU12 -> 0.16801914 | CV15: =CV13/CV12 -> 0.060624807 | CW15: =CW13/CW12 -> 0.077499274 | CX15: =CX13/CX12 -> 0.055012352 | CY15: =CY13/CY12 -> 0.078667781 | CZ15: =CZ13/CZ12 -> 0.05397762 | DA15: =DA13/DA12 -> 0.10464886 | ... EC15: =EC13/EC12 -> 0.040551526 | ED15: x
A16: Online % | AZ16: =AZ14/AZ$12 -> 0.83021244 | BA16: =BA14/BA$12 -> 0.82653306 | BB16: =BB14/BB$12 -> 0.83557206 | BC16: =BC14/BC$12 -> 0.68596898 | BD16: =BD14/BD$12 -> 0.78428299 | BE16: =BE14/BE$12 -> 0.75025878 | BF16: =BF14/BF$12 -> 0.75810612 | BG16: =BG14/BG$12 -> 0.79763804 | ... CS16: =CS14/CS$12 -> 0.95944847 | CT16: =CT14/CT12 -> 0.82914544 | CU16: =CU14/CU12 -> 0.83198086 | CV16: =CV14/CV12 -> 0.93937519 | CW16: =CW14/CW12 -> 0.92250073 | CX16: =CX14/CX12 -> 0.94498765 | CY16: =CY14/CY12 -> 0.92133222 | CZ16: =CZ14/CZ12 -> 0.94602238 | DA16: =DA14/DA12 -> 0.89535114 | ... EC16: =EC14/EC12 -> 0.95944847 | ED16: x
ED17: x
A18: Average Selling Price | B18: =B7/B12 -> 3970.8564 | C18: =C7/C12 -> 4166.8194 | D18: =D7/D12 -> 3844.2636 | E18: =E7/E12 -> 3962.5747 | F18: =F7/F12 -> 3873.6431 | G18: =G7/G12 -> 3875.0994 | H18: =H7/H12 -> 3860.238 | I18: =I7/I12 -> 3623.3712 | ... CS18: =CS7/CS12 -> 11257.883 | CT18: =SUM(CH7:CS7)/SUM(CH12:CS12)*(1+CT19) -> 9913.9483 | CU18: =CT18*(1+CU19) -> 9913.9483 | CV18: =CU18*(1+CV19) -> 9913.9483 | CW18: =CV18*(1+CW19) -> 9913.9483 | CX18: =CW18*(1+CX19) -> 9913.9483 | CY18: =CX18*(1+CY19) -> 9913.9483 | CZ18: =CY18*(1+CZ19) -> 9913.9483 | DA18: =CZ18*(1+DA19) -> 9913.9483 | DB18: =DA18*(1+DB19) -> 9913.9483 | ... EC18: =EB18*(1+EC19) -> 9913.9483 | ED18: x
A19: ASP Growth % | BJ19: =BJ18/BI18-1 -> 0.11893015 | BK19: =BK18/BJ18-1 -> 0.043545781 | BL19: =BL18/BK18-1 -> 0.034703137 | BM19: =BM18/BL18-1 -> -0.049328764 | BN19: =BN18/BM18-1 -> -0.041114214 | BO19: =BO18/BN18-1 -> -0.033415845 | BP19: =BP18/BO18-1 -> 0.10761976 | BQ19: =BQ18/BP18-1 -> -0.016095231 | ... CS19: =CS18/CR18-1 -> 0.017026615 | CT19: -0.02 | DE19: 0 | DQ19: 0 | ED19: x
ED20: x
A21: Returns | ED21: x
A22: Return Amount | B22: 0 | C22: 0 | D22: 0 | E22: 0 | F22: 0 | G22: 0 | H22: 0 | I22: 0 | J22: 0 | K22: 0 | L22: 0 | M22: 0 | N22: 73665.555 | O22: 18545.06 | P22: 35350.414 | Q22: 313486.29 | R22: 1159355.2 | S22: 1898625.9 | T22: 1537513.1 | U22: 1643258.5 | V22: 3134468.3 | W22: 3493815.9 | X22: 2214325.7 | Y22: 681691.8 | Z22: 58689 | AA22: 78042.06 | AB22: 302378.05 | AC22: 90474.93 | AD22: 203264.43 | AE22: 1361023.8 | AF22: 2293737.3 | AG22: 2573237.4 | AH22: 2807817 | AI22: 3084430.9 | AJ22: 3797965.8 | AK22: 4332916.3 | AL22: 3505842.3 | AM22: 4420191.5 | AN22: 8957793.6 | AO22: 13662088 | AP22: 16041871 | AQ22: 25276687 | AR22: 33122634 | AS22: 23397431 | AT22: 30706134 | AU22: 32573536 | AV22: 43288241 | AW22: 50451902 | AX22: 49613456 | AY22: 64881764 | AZ22: =AZ23+AZ24 -> 69152023 | BA22: =BA23+BA24 -> 64276477 | BB22: =BB23+BB24 -> 61835594 | BC22: =BC23+BC24 -> 53480848 | BD22: =BD23+BD24 -> 46389583 | BE22: =BE23+BE24 -> 53529111 | BF22: =BF23+BF24 -> 62969264 | BG22: =BG23+BG24 -> 57422683 | ... EC22: =EC23+EC24 -> 1.2733613e+08 | ED22: x
A23: Offline | AZ23: 584761.33 | BA23: 130274.59 | BB23: 163329.98 | BC23: 380127.04 | BD23: 1177382.5 | BE23: 2259684.6 | BF23: 308900.99 | BG23: 249670.93 | BH23: 568887.69 | BI23: 1351325 | BJ23: 489349 | BK23: 596455.25 | BL23: 152981.59 | BM23: 200262.42 | BN23: 27457.577 | BO23: 201581.7 | BP23: 2088827.9 | BQ23: 270666.24 | BR23: 88826.571 | BS23: 720660.15 | BT23: 1462117.2 | BU23: 1052057 | BV23: 645068.35 | BW23: 639875.17 | BX23: 851158.77 | BY23: 95498.433 | BZ23: 100441.8 | CA23: 86477.185 | CB23: 313479.17 | CC23: 280926.05 | CD23: 185949.37 | CE23: 12510.888 | CF23: 62892.962 | CG23: 90180.167 | CH23: 147495.14 | CI23: 1251985.5 | CJ23: 55430.529 | CK23: 246236.78 | CL23: 54944.39 | CM23: 93690.25 | CN23: 29481.83 | CO23: 111605.68 | CP23: 311799.45 | CQ23: 120490.87 | CR23: 29857.06 | CS23: 112658.46 | CT23: =CS23/CS27*CT27 -> 270750.95 | CU23: =CT23/CT27*CU27 -> 276072.24 | CV23: =CU23/CU27*CV27 -> 94815.742 | CW23: =CV23/CV27*CW27 -> 121059.38 | CX23: =CW23/CW27*CX27 -> 80121.721 | CY23: =CX23/CX27*CY27 -> 99623.045 | CZ23: =CY23/CY27*CZ27 -> 80212.425 | DA23: =CZ23/CZ27*DA27 -> 191385.09 | ... EC23: =EB23/EB27*EC27 -> 109632.49 | ED23: x
A24: Online | AZ24: 68567261 | BA24: 64146203 | BB24: 61672264 | BC24: 53100721 | BD24: 45212201 | BE24: 51269427 | BF24: 62660363 | BG24: 57173013 | BH24: 57521228 | BI24: 61272930 | BJ24: 76047181 | BK24: 72098825 | BL24: 55542143 | BM24: 59960809 | BN24: 56538940 | BO24: 50706878 | BP24: 42722467 | BQ24: 33017650 | BR24: 39291725 | BS24: 37875847 | BT24: 40077373 | BU24: 34575290 | BV24: 38382767 | BW24: 40540331 | BX24: 36969260 | BY24: 38326106 | BZ24: 38440252 | CA24: 41192892 | CB24: 38187234 | CC24: 35123003 | CD24: 38377281 | CE24: 34152064 | CF24: 31020347 | CG24: 38758008 | CH24: 42143225 | CI24: 41219534 | CJ24: 59098386 | CK24: 46927371 | CL24: 50189998 | CM24: 40320148 | CN24: 43616763 | CO24: 43585970 | CP24: 57750700 | CQ24: 58166177 | CR24: 62582269 | CS24: 66033595 | CT24: =CS24/CS28*CT28 -> 64446297 | CU24: =CT24/CT28*CU28 -> 67050368 | CV24: =CU24/CU28*CV28 -> 72059793 | CW24: =CV24/CV28*CW28 -> 70679161 | CX24: =CW24/CW28*CX28 -> 67505635 | CY24: =CX24/CX28*CY28 -> 57227268 | CZ24: =CY24/CY28*CZ28 -> 68953000 | DA24: =CZ24/CZ28*DA28 -> 80313925 | ... EC24: =EB24/EB28*EC28 -> 1.2722649e+08 | ED24: x
ED25: x
A26: Devices | B26: 0 | C26: 0 | D26: 0 | E26: 0 | F26: 0 | G26: 0 | H26: 0 | I26: 0 | J26: 0 | K26: 0 | L26: 0 | M26: 0 | N26: 9 | O26: 1 | P26: 4 | Q26: 31 | R26: 137 | S26: 193 | T26: 159 | U26: 148 | V26: 325 | W26: 451 | X26: 337 | Y26: 109 | Z26: 9 | AA26: 1 | AB26: 42 | AC26: 9 | AD26: 41 | AE26: 163 | AF26: 338 | AG26: 440 | AH26: 464 | AI26: 386 | AJ26: 487 | AK26: 544 | AL26: 529 | AM26: 751 | AN26: 1454 | AO26: 2406 | AP26: 3125 | AQ26: 4565 | AR26: 5997 | AS26: 4301 | AT26: 5405 | AU26: 5899 | AV26: 7326 | AW26: 8324 | AX26: 8454 | AY26: 11659 | AZ26: =AZ27+AZ28 -> 12670 | BA26: =BA27+BA28 -> 9847 | BB26: =BB27+BB28 -> 9688 | BC26: =BC27+BC28 -> 8687 | BD26: =BD27+BD28 -> 8023 | BE26: =BE27+BE28 -> 8041 | BF26: =BF27+BF28 -> 8690 | BG26: =BG27+BG28 -> 7618 | ... EC26: =EC27+EC28 -> 9221.2526 | ED26: x
A27: Offline | AZ27: 98 | BA27: 18 | BB27: 19 | BC27: 90 | BD27: 235 | BE27: 236 | BF27: 39 | BG27: 18 | BH27: 44 | BI27: 301 | BJ27: 33 | BK27: 36 | BL27: 13 | BM27: 11 | BN27: 3 | BO27: 16 | BP27: 101 | BQ27: 15 | BR27: 6 | BS27: 37 | BT27: 65 | BU27: 53 | BV27: 32 | BW27: 25 | BX27: 47 | BY27: 7 | BZ27: 5 | CA27: 4 | CB27: 20 | CC27: 19 | CD27: 12 | CE27: 1 | CF27: 4 | CG27: 5 | CH27: 7 | CI27: 38 | CJ27: 5 | CK27: 11 | CL27: 3 | CM27: 7 | CN27: 2 | CO27: 15 | CP27: 20 | CQ27: 5 | CR27: 2 | CS27: 10 | CT27: =CT13*CT30 -> 24.0329 | CU27: =CU13*CU30 -> 24.505238 | CV27: =CV13*CV30 -> 8.4162114 | CW27: =CW13*CW30 -> 10.745699 | CX27: =CX13*CX30 -> 7.1119134 | CY27: =CY13*CY30 -> 8.8429262 | CZ27: =CZ13*CZ30 -> 7.1199646 | DA27: =DA13*DA30 -> 16.98808 | ... EC27: =EC13*EC30 -> 9.7314029 | ED27: x
A28: Online | AZ28: 12572 | BA28: 9829 | BB28: 9669 | BC28: 8597 | BD28: 7788 | BE28: 7805 | BF28: 8651 | BG28: 7600 | BH28: 7097 | BI28: 7443 | BJ28: 9147 | BK28: 8142 | BL28: 6160 | BM28: 6257 | BN28: 6524 | BO28: 5654 | BP28: 4701 | BQ28: 3420 | BR28: 3691 | BS28: 3335 | BT28: 3361 | BU28: 3021 | BV28: 3318 | BW28: 3853 | BX28: 3974 | BY28: 4020 | BZ28: 3975 | CA28: 4193 | CB28: 3866 | CC28: 3564 | CD28: 3940 | CE28: 3084 | CF28: 2578 | CG28: 3041 | CH28: 3414 | CI28: 3184 | CJ28: 4800.6316 | CK28: 3809 | CL28: 3994 | CM28: 3306 | CN28: 3861 | CO28: 3927 | CP28: 4814 | CQ28: 4246 | CR28: 4440 | CS28: 4781 | CT28: =CT14*CT31 -> 4666.0756 | CU28: =CU14*CU31 -> 4854.6169 | CV28: =CV14*CV31 -> 5217.312 | CW28: =CW14*CW31 -> 5117.3507 | CX28: =CX14*CX31 -> 4887.5794 | CY28: =CY14*CY31 -> 4143.3995 | CZ28: =CZ14*CZ31 -> 4992.3723 | DA28: =DA14*DA31 -> 5814.9321 | ... EC28: =EC14*EC31 -> 9211.5212 | ED28: x
ED29: x
A30: Offline Returns % | AZ30: =AZ27/AZ13 -> 0.010382456 | BA30: =BA27/BA13 -> 0.0016583748 | BB30: =BB27/BB13 -> 0.0017657993 | BC30: =BC27/BC13 -> 0.0041273044 | BD30: =BD27/BD13 -> 0.016908908 | BE30: =BE27/BE13 -> 0.013585861 | BF30: =BF27/BF13 -> 0.0018650471 | BG30: =BG27/BG13 -> 0.0011633167 | ... CS30: =CS27/CS13 -> 0.0041367225 | CT30: =AVERAGE(CH30:CS30) -> 0.0020178503 | CU30: =CT30 -> 0.0020178503 | CV30: =CU30 -> 0.0020178503 | CW30: =CV30 -> 0.0020178503 | CX30: =CW30 -> 0.0020178503 | CY30: =CX30 -> 0.0020178503 | CZ30: =CY30 -> 0.0020178503 | DA30: =CZ30 -> 0.0020178503 | DB30: =DA30 -> 0.0020178503 | ... EC30: =EB30 -> 0.0020178503 | ED30: x
A31: Online Returns % | AZ31: =AZ28/AZ14 -> 0.27239243 | BA31: =BA28/BA14 -> 0.19005356 | BB31: =BB28/BB14 -> 0.17683206 | BC31: =BC28/BC14 -> 0.18048412 | BD31: =BD28/BD14 -> 0.15412931 | BE31: =BE28/BE14 -> 0.14956405 | BF31: =BF28/BF14 -> 0.13200378 | BG31: =BG28/BG14 -> 0.12461264 | ... CS31: =CS28/CS14 -> 0.083591223 | CT31: =AVERAGE(CH31:CS31) -> 0.080729152 | CU31: =CT31 -> 0.080729152 | CV31: =CU31 -> 0.080729152 | CW31: =CV31 -> 0.080729152 | CX31: =CW31 -> 0.080729152 | CY31: =CX31 -> 0.080729152 | CZ31: =CY31 -> 0.080729152 | DA31: =CZ31 -> 0.080729152 | DB31: =DA31 -> 0.080729152 | ... EC31: =EB31 -> 0.080729152 | ED31: x
A32: Overall Returns % | B32: =B26/B12 -> 0 | C32: =C26/C12 -> 0 | D32: =D26/D12 -> 0 | E32: =E26/E12 -> 0 | F32: =F26/F12 -> 0 | G32: =G26/G12 -> 0 | H32: =H26/H12 -> 0 | I32: =I26/I12 -> 0 | ... EC32: =EC26/EC12 -> 0.077537289 | ED32: x
ED33: x
A34: #RTO | BJ34: 2808 | BK34: 2199 | BL34: 1827 | BM34: 1972 | BN34: 2125 | BO34: 1865 | BP34: 2217 | BQ34: 1759 | BR34: 1747 | BS34: 1552 | BT34: 1601 | BU34: 1548 | BV34: 1590 | BW34: 1999 | BX34: 2365 | BY34: 2005 | BZ34: 2244 | CA34: 2492 | CB34: 1813 | CC34: 2113 | CD34: 2171 | CE34: 1344 | CF34: 912 | CG34: 1088 | CH34: 1054 | CI34: 1054 | CJ34: 1012 | CK34: 1342 | CL34: 1336 | CM34: 1834 | CN34: 1779 | CO34: 1744 | CP34: 2046 | CQ34: 1301 | CR34: 1320 | CS34: 1363 | CT34: =CS34/CS26*CT26 -> 1334.2972 | CU34: =CT34/CT26*CU26 -> 1388.07 | CV34: =CU34/CU26*CV26 -> 1486.6766 | CW34: =CV34/CV26*CW26 -> 1458.9012 | CX34: =CW34/CW26*CX26 -> 1392.4993 | CY34: =CX34/CX26*CY26 -> 1181.2787 | CZ34: =CY34/CY26*CZ26 -> 1422.3143 | DA34: =CZ34/CZ26*DA26 -> 1659.1332 | ... EC34: =EB34/EB26*EC26 -> 2623.3703 | ED34: x
A35: #Quality return | BJ35: =BJ26-BJ34 -> 6372 | BK35: =BK26-BK34 -> 5979 | BL35: =BL26-BL34 -> 4346 | BM35: =BM26-BM34 -> 4296 | BN35: =BN26-BN34 -> 4402 | BO35: =BO26-BO34 -> 3805 | BP35: =BP26-BP34 -> 2585 | BQ35: =BQ26-BQ34 -> 1676 | ... EC35: =EC26-EC34 -> 6597.8823 | ED35: x
ED36: x
A37: Revenue Pre Tax (after returns) | B37: =B7-B22 -> 127373162 | C37: =C7-C22 -> 119525214 | D37: =D7-D22 -> 1.3361892e+08 | E37: =E7-E22 -> 1.5572126e+08 | F37: =F7-F22 -> 1.8292117e+08 | G37: =G7-G22 -> 190468885 | H37: =H7-H22 -> 203496304 | I37: =I7-I22 -> 191306750 | ... AY37: =AY7-AY22 -> 353948479 | AZ37: =AZ38+AZ39 -> 2.5371895e+08 | BA37: =BA38+BA39 -> 2.9535237e+08 | BB37: =BB38+BB39 -> 3.1485956e+08 | BC37: =BC38+BC39 -> 3.2301777e+08 | BD37: =BD38+BD39 -> 3.7999148e+08 | BE37: =BE38+BE39 -> 4.1113798e+08 | BF37: =BF38+BF39 -> 5.2349925e+08 | BG37: =BG38+BG39 -> 4.7201029e+08 | ... EC37: =EC38+EC39 -> 1.0516969e+09 | ED37: x
A38: Offline | AZ38: =AZ8-AZ23 -> 57315452 | BA38: =BA8-BA23 -> 62354498 | BB38: =BB8-BB23 -> 63129962 | BC38: =BC8-BC23 -> 1.123392e+08 | BD38: =BD8-BD23 -> 1.0043798e+08 | BE38: =BE8-BE23 -> 1.2020981e+08 | BF38: =BF8-BF23 -> 1.4746099e+08 | BG38: =BG8-BG23 -> 1.1183517e+08 | ... EC38: =EC8-EC23 -> 45874397 | ED38: x
A39: Online | AZ39: =AZ9-AZ24 -> 1.964035e+08 | BA39: =BA9-BA24 -> 2.3299787e+08 | BB39: =BB9-BB24 -> 2.5172959e+08 | BC39: =BC9-BC24 -> 2.1067857e+08 | BD39: =BD9-BD24 -> 2.795535e+08 | BE39: =BE9-BE24 -> 2.9092817e+08 | BF39: =BF9-BF24 -> 3.7603826e+08 | BG39: =BG9-BG24 -> 3.6017512e+08 | ... EC39: =EC9-EC24 -> 1.0058225e+09 | ED39: x
ED40: x
...

Sheet P&L Summary
B2: Cashify | J2: Common Size across the years
B3: Amounts in ₹ Crores | J3: Particulars | K3: FY24A | L3: FY25A | M3: FY26A | N3: FY27E | O3: FY28E | P3: FY29E
B4: Particulars | C4: FY24A | D4: FY25A | E4: FY26A | F4: FY27E | G4: FY28E | H4: FY29E | J4: Revenue Post Tax (Rs. Cr) | K4: 1001.3779 | L4: 1158.3452 | M4: 1719.155 | N4: 2186.6364 | O4: 2658.0117 | P4: 3109.1173
B5: GMV (after returns) | C5: =('Consolidated - P&L'!FE34)/10000000 -> 1482.0928 | D5: =('Consolidated - P&L'!FF34)/10000000 -> 1744.9847 | E5: =('Consolidated - P&L'!FG34)/10000000 -> 2441.5956 | F5: =('Consolidated - P&L'!FH34)/10000000 -> 3117.7265 | G5: =('Consolidated - P&L'!FI34)/10000000 -> 3776.2949 | H5: =('Consolidated - P&L'!FJ34)/10000000 -> 4397.3352 | J5: GMV (after returns) | K5: =('Consolidated - P&L'!FM34)/10000000 -> 0 | L5: =('Consolidated - P&L'!FN34)/10000000 -> 0 | M5: =('Consolidated - P&L'!FO34)/10000000 -> 0 | N5: =('Consolidated - P&L'!FP34)/10000000 -> 0 | O5: =('Consolidated - P&L'!FQ34)/10000000 -> 0 | P5: =('Consolidated - P&L'!FR34)/10000000 -> 0
B6: Non- Repair | C6: =('Consolidated - P&L'!FE35)/10000000 -> 371.80841 | D6: =('Consolidated - P&L'!FF35)/10000000 -> 403.94291 | E6: =('Consolidated - P&L'!FG35)/10000000 -> 608.30257 | F6: =('Consolidated - P&L'!FH35)/10000000 -> 783.16183 | G6: =('Consolidated - P&L'!FI35)/10000000 -> 978.95228 | H6: =('Consolidated - P&L'!FJ35)/10000000 -> 1174.7427 | J6: Non- Repair | K6: =('Consolidated - P&L'!FM35)/10000000 -> 0 | L6: =('Consolidated - P&L'!FN35)/10000000 -> 0 | M6: =('Consolidated - P&L'!FO35)/10000000 -> 0 | N6: =('Consolidated - P&L'!FP35)/10000000 -> 0 | O6: =('Consolidated - P&L'!FQ35)/10000000 -> 0 | P6: =('Consolidated - P&L'!FR35)/10000000 -> 0
B7: Refurbished | C7: =('Consolidated - P&L'!FE36)/10000000 -> 584.05711 | D7: =('Consolidated - P&L'!FF36)/10000000 -> 700.4068 | E7: =('Consolidated - P&L'!FG36)/10000000 -> 1051.848 | F7: =('Consolidated - P&L'!FH36)/10000000 -> 1333.9691 | G7: =('Consolidated - P&L'!FI36)/10000000 -> 1603.0075 | H7: =('Consolidated - P&L'!FJ36)/10000000 -> 1854.3997 | J7: Refurbished | K7: =('Consolidated - P&L'!FM36)/10000000 -> 0 | L7: =('Consolidated - P&L'!FN36)/10000000 -> 0 | M7: =('Consolidated - P&L'!FO36)/10000000 -> 0 | N7: =('Consolidated - P&L'!FP36)/10000000 -> 0 | O7: =('Consolidated - P&L'!FQ36)/10000000 -> 0 | P7: =('Consolidated - P&L'!FR36)/10000000 -> 0
B8: Market Place | C8: =('Consolidated - P&L'!FE37)/10000000 -> 493.51541 | D8: =('Consolidated - P&L'!FF37)/10000000 -> 599.40465 | E8: =('Consolidated - P&L'!FG37)/10000000 -> 717.03825 | F8: =('Consolidated - P&L'!FH37)/10000000 -> 923.18675 | G8: =('Consolidated - P&L'!FI37)/10000000 -> 1107.8241 | H8: =('Consolidated - P&L'!FJ37)/10000000 -> 1273.9977 | J8: Market Place | K8: =('Consolidated - P&L'!FM37)/10000000 -> 0 | L8: =('Consolidated - P&L'!FN37)/10000000 -> 0 | M8: =('Consolidated - P&L'!FO37)/10000000 -> 0 | N8: =('Consolidated - P&L'!FP37)/10000000 -> 0 | O8: =('Consolidated - P&L'!FQ37)/10000000 -> 0 | P8: =('Consolidated - P&L'!FR37)/10000000 -> 0
B9: Screen Pro + Accessories | C9: =('Consolidated - P&L'!FE38)/10000000 -> 30.984226 | D9: =('Consolidated - P&L'!FF38)/10000000 -> 38.001386 | E9: =('Consolidated - P&L'!FG38)/10000000 -> 59.804978 | F9: =('Consolidated - P&L'!FH38)/10000000 -> 72.807056 | G9: =('Consolidated - P&L'!FI38)/10000000 -> 81.90918 | H9: =('Consolidated - P&L'!FJ38)/10000000 -> 89.593241 | J9: Screen Pro + Accessories | K9: =('Consolidated - P&L'!FM38)/10000000 -> 0 | L9: =('Consolidated - P&L'!FN38)/10000000 -> 0 | M9: =('Consolidated - P&L'!FO38)/10000000 -> 0 | N9: =('Consolidated - P&L'!FP38)/10000000 -> 0 | O9: =('Consolidated - P&L'!FQ38)/10000000 -> 0 | P9: =('Consolidated - P&L'!FR38)/10000000 -> 0
B10: Enterprise Sales | C10: =('Consolidated - P&L'!FE39)/10000000 -> 1.7276083 | D10: =('Consolidated - P&L'!FF39)/10000000 -> 3.2290095 | E10: =('Consolidated - P&L'!FG39)/10000000 -> 4.6017858 | F10: =('Consolidated - P&L'!FH39)/10000000 -> 4.6017858 | G10: =('Consolidated - P&L'!FI39)/10000000 -> 4.6017858 | H10: =('Consolidated - P&L'!FJ39)/10000000 -> 4.6017858 | J10: Enterprise Sales | K10: =('Consolidated - P&L'!FM39)/10000000 -> 0 | L10: =('Consolidated - P&L'!FN39)/10000000 -> 0 | M10: =('Consolidated - P&L'!FO39)/10000000 -> 0 | N10: =('Consolidated - P&L'!FP39)/10000000 -> 0 | O10: =('Consolidated - P&L'!FQ39)/10000000 -> 0 | P10: =('Consolidated - P&L'!FR39)/10000000 -> 0
B12: Revenue Post Tax (after returns) | C12: =('Consolidated - P&L'!FE63)/10000000 -> 1001.3779 | D12: =('Consolidated - P&L'!FF63)/10000000 -> 1158.3452 | E12: =('Consolidated - P&L'!FG63)/10000000 -> 1719.155 | F12: =('Consolidated - P&L'!FH63)/10000000 -> 2186.6364 | G12: =('Consolidated - P&L'!FI63)/10000000 -> 2658.0117 | H12: =('Consolidated - P&L'!FJ63)/10000000 -> 3109.1173 | J12: Revenue Post Tax | K12: =C12/C$12 -> 1 | L12: =D12/D$12 -> 1 | M12: =E12/E$12 -> 1 | N12: =F12/F$12 -> 1 | O12: =G12/G$12 -> 1 | P12: =H12/H$12 -> 1
B13: Non- Repair | C13: =('Consolidated - P&L'!FE64)/10000000 -> 363.11378 | D13: =('Consolidated - P&L'!FF64)/10000000 -> 393.89294 | E13: =('Consolidated - P&L'!FG64)/10000000 -> 589.27142 | F13: =('Consolidated - P&L'!FH64)/10000000 -> 755.58035 | G13: =('Consolidated - P&L'!FI64)/10000000 -> 944.47544 | H13: =('Consolidated - P&L'!FJ64)/10000000 -> 1133.3705 | J13: Non- Repair | K13: =('Consolidated - P&L'!FM64)/10000000 -> 0 | L13: =('Consolidated - P&L'!FN64)/10000000 -> 0 | M13: =('Consolidated - P&L'!FO64)/10000000 -> 0 | N13: =('Consolidated - P&L'!FP64)/10000000 -> 0 | O13: =('Consolidated - P&L'!FQ64)/10000000 -> 0 | P13: =('Consolidated - P&L'!FR64)/10000000 -> 0
B14: Refurbished | C14: =('Consolidated - P&L'!FE65)/10000000 -> 558.41442 | D14: =('Consolidated - P&L'!FF65)/10000000 -> 665.69803 | E14: =('Consolidated - P&L'!FG65)/10000000 -> 997.76044 | F14: =('Consolidated - P&L'!FH65)/10000000 -> 1267.2722 | G14: =('Consolidated - P&L'!FI65)/10000000 -> 1523.2108 | H14: =('Consolidated - P&L'!FJ65)/10000000 -> 1762.0933 | J14: Refurbished | K14: =('Consolidated - P&L'!FM65)/10000000 -> 0 | L14: =('Consolidated - P&L'!FN65)/10000000 -> 0 | M14: =('Consolidated - P&L'!FO65)/10000000 -> 0 | N14: =('Consolidated - P&L'!FP65)/10000000 -> 0 | O14: =('Consolidated - P&L'!FQ65)/10000000 -> 0 | P14: =('Consolidated - P&L'!FR65)/10000000 -> 0
B15: Market Place | C15: =('Consolidated - P&L'!FE66)/10000000 -> 52.097639 | D15: =('Consolidated - P&L'!FF66)/10000000 -> 63.813216 | E15: =('Consolidated - P&L'!FG66)/10000000 -> 81.954121 | F15: =('Consolidated - P&L'!FH66)/10000000 -> 105.51593 | G15: =('Consolidated - P&L'!FI66)/10000000 -> 126.61912 | H15: =('Consolidated - P&L'!FJ66)/10000000 -> 145.61199 | J15: Market Place | K15: =('Consolidated - P&L'!FM66)/10000000 -> 0 | L15: =('Consolidated - P&L'!FN66)/10000000 -> 0 | M15: =('Consolidated - P&L'!FO66)/10000000 -> 0 | N15: =('Consolidated - P&L'!FP66)/10000000 -> 0 | O15: =('Consolidated - P&L'!FQ66)/10000000 -> 0 | P15: =('Consolidated - P&L'!FR66)/10000000 -> 0
B16: Screen Pro + Accessories | C16: =('Consolidated - P&L'!FE67)/10000000 -> 26.257819 | D16: =('Consolidated - P&L'!FF67)/10000000 -> 32.204564 | E16: =('Consolidated - P&L'!FG67)/10000000 -> 46.269226 | F16: =('Consolidated - P&L'!FH67)/10000000 -> 54.368071 | G16: =('Consolidated - P&L'!FI67)/10000000 -> 59.80646 | H16: =('Consolidated - P&L'!FJ67)/10000000 -> 64.141757 | J16: Screen Pro + Accessories | K16: =('Consolidated - P&L'!FM67)/10000000 -> 0 | L16: =('Consolidated - P&L'!FN67)/10000000 -> 0 | M16: =('Consolidated - P&L'!FO67)/10000000 -> 0 | N16: =('Consolidated - P&L'!FP67)/10000000 -> 0 | O16: =('Consolidated - P&L'!FQ67)/10000000 -> 0 | P16: =('Consolidated - P&L'!FR67)/10000000 -> 0
B17: Enterprise Sales | C17: =('Consolidated - P&L'!FE68)/10000000 -> 1.4942548 | D17: =('Consolidated - P&L'!FF68)/10000000 -> 2.7364487 | E17: =('Consolidated - P&L'!FG68)/10000000 -> 3.8998185 | F17: =('Consolidated - P&L'!FH68)/10000000 -> 3.8998185 | G17: =('Consolidated - P&L'!FI68)/10000000 -> 3.8998185 | H17: =('Consolidated - P&L'!FJ68)/10000000 -> 3.8998185 | J17: Enterprise Sales | K17: =('Consolidated - P&L'!FM68)/10000000 -> 0 | L17: =('Consolidated - P&L'!FN68)/10000000 -> 0 | M17: =('Consolidated - P&L'!FO68)/10000000 -> 0 | N17: =('Consolidated - P&L'!FP68)/10000000 -> 0 | O17: =('Consolidated - P&L'!FQ68)/10000000 -> 0 | P17: =('Consolidated - P&L'!FR68)/10000000 -> 0
B18: Revenue Growth % | D18: =D12/C12-1 -> 0.1567513 | E18: =E12/D12-1 -> 0.48414742 | F18: =F12/E12-1 -> 0.27192507 | G18: =G12/F12-1 -> 0.21557096 | H18: =H12/G12-1 -> 0.16971545 | J18: Revenue Growth % | L18: =L12/K12-1 -> 0 | M18: =M12/L12-1 -> 0 | N18: =N12/M12-1 -> 0 | O18: =O12/N12-1 -> 0 | P18: =P12/O12-1 -> 0
B20: #Transactions | C20: ='Consolidated - P&L'!FE78 -> 1400717 | D20: ='Consolidated - P&L'!FF78 -> 1422394 | E20: ='Consolidated - P&L'!FG78 -> 1830710.6 | F20: ='Consolidated - P&L'!FH78 -> 2330266.5 | G20: ='Consolidated - P&L'!FI78 -> 2821043.9 | H20: ='Consolidated - P&L'!FJ78 -> 3291993.7 | J20: #Transactions | K20: ='Consolidated - P&L'!FM78 -> 0 | L20: ='Consolidated - P&L'!FN78 -> 0 | M20: ='Consolidated - P&L'!FO78 -> 0 | N20: ='Consolidated - P&L'!FP78 -> 0 | O20: ='Consolidated - P&L'!FQ78 -> 0 | P20: ='Consolidated - P&L'!FR78 -> 0
B21: Non- Repair | C21: ='Consolidated - P&L'!FE79 -> 459194 | D21: ='Consolidated - P&L'!FF79 -> 447334 | E21: ='Consolidated - P&L'!FG79 -> 613323.31 | F21: ='Consolidated - P&L'!FH79 -> 815479.92 | G21: ='Consolidated - P&L'!FI79 -> 1019349.9 | H21: ='Consolidated - P&L'!FJ79 -> 1223219.9 | J21: Non- Repair | K21: ='Consolidated - P&L'!FM79 -> 0 | L21: ='Consolidated - P&L'!FN79 -> 0 | M21: ='Consolidated - P&L'!FO79 -> 0 | N21: ='Consolidated - P&L'!FP79 -> 0 | O21: ='Consolidated - P&L'!FQ79 -> 0 | P21: ='Consolidated - P&L'!FR79 -> 0
B22: Refurbished | C22: ='Consolidated - P&L'!FE80 -> 243372 | D22: ='Consolidated - P&L'!FF80 -> 253977 | E22: ='Consolidated - P&L'!FG80 -> 359093.29 | F22: ='Consolidated - P&L'!FH80 -> 441919.04 | G22: ='Consolidated - P&L'!FI80 -> 514252.95 | H22: ='Consolidated - P&L'!FJ80 -> 588216.62 | J22: Refurbished | K22: ='Consolidated - P&L'!FM80 -> 0 | L22: ='Consolidated - P&L'!FN80 -> 0 | M22: ='Consolidated - P&L'!FO80 -> 0 | N22: ='Consolidated - P&L'!FP80 -> 0 | O22: ='Consolidated - P&L'!FQ80 -> 0 | P22: ='Consolidated - P&L'!FR80 -> 0
B23: Market Place | C23: ='Consolidated - P&L'!FE81 -> 698151 | D23: ='Consolidated - P&L'!FF81 -> 721083 | E23: ='Consolidated - P&L'!FG81 -> 858294 | F23: ='Consolidated - P&L'!FH81 -> 1072867.5 | G23: ='Consolidated - P&L'!FI81 -> 1287441 | H23: ='Consolidated - P&L'!FJ81 -> 1480557.1 | J23: Market Place | K23: ='Consolidated - P&L'!FM81 -> 0 | L23: ='Consolidated - P&L'!FN81 -> 0 | M23: ='Consolidated - P&L'!FO81 -> 0 | N23: ='Consolidated - P&L'!FP81 -> 0 | O23: ='Consolidated - P&L'!FQ81 -> 0 | P23: ='Consolidated - P&L'!FR81 -> 0
B25: Gross Margin 1 | C25: =('Consolidated - P&L'!FE101)/10000000 -> 174.53873 | D25: =('Consolidated - P&L'!FF101)/10000000 -> 242.71886 | E25: =('Consolidated - P&L'!FG101)/10000000 -> 345.32878 | F25: =('Consolidated - P&L'!FH101)/10000000 -> 431.70878 | G25: =('Consolidated - P&L'!FI101)/10000000 -> 524.96996 | H25: =('Consolidated - P&L'!FJ101)/10000000 -> 612.95692 | J25: Gross Margin 1 | K25: =C25/C$12 -> 0.17429857 | L25: =D25/D$12 -> 0.20953932 | M25: =E25/E$12 -> 0.20087123 | N25: =F25/F$12 -> 0.19743053 | O25: =G25/G$12 -> 0.19750476 | P25: =H25/H$12 -> 0.19714821
B26: Non- Repair | C26: =('Consolidated - P&L'!FE102)/10000000 -> 14.125598 | D26: =('Consolidated - P&L'!FF102)/10000000 -> 27.054408 | E26: =('Consolidated - P&L'!FG102)/10000000 -> 44.508853 | F26: =('Consolidated - P&L'!FH102)/10000000 -> 55.450024 | G26: =('Consolidated - P&L'!FI102)/10000000 -> 77.616632 | H26: =('Consolidated - P&L'!FJ102)/10000000 -> 103.00523 | J26: Non- Repair | K26: =('Consolidated - P&L'!FM102)/10000000 -> 0 | L26: =('Consolidated - P&L'!FN102)/10000000 -> 0 | M26: =('Consolidated - P&L'!FO102)/10000000 -> 0 | N26: =('Consolidated - P&L'!FP102)/10000000 -> 0 | O26: =('Consolidated - P&L'!FQ102)/10000000 -> 0 | P26: =('Consolidated - P&L'!FR102)/10000000 -> 0
B27: Refurbished | C27: =('Consolidated - P&L'!FE103)/10000000 -> 99.369447 | D27: =('Consolidated - P&L'!FF103)/10000000 -> 139.47381 | E27: =('Consolidated - P&L'!FG103)/10000000 -> 201.88745 | F27: =('Consolidated - P&L'!FH103)/10000000 -> 253.4483 | G27: =('Consolidated - P&L'!FI103)/10000000 -> 302.87904 | H27: =('Consolidated - P&L'!FJ103)/10000000 -> 346.03004 | J27: Refurbished | K27: =('Consolidated - P&L'!FM103)/10000000 -> 0 | L27: =('Consolidated - P&L'!FN103)/10000000 -> 0 | M27: =('Consolidated - P&L'!FO103)/10000000 -> 0 | N27: =('Consolidated - P&L'!FP103)/10000000 -> 0 | O27: =('Consolidated - P&L'!FQ103)/10000000 -> 0 | P27: =('Consolidated - P&L'!FR103)/10000000 -> 0
B28: Market Place | C28: =('Consolidated - P&L'!FE104)/10000000 -> 52.097639 | D28: =('Consolidated - P&L'!FF104)/10000000 -> 63.813216 | E28: =('Consolidated - P&L'!FG104)/10000000 -> 81.954121 | F28: =('Consolidated - P&L'!FH104)/10000000 -> 105.51593 | G28: =('Consolidated - P&L'!FI104)/10000000 -> 126.61912 | H28: =('Consolidated - P&L'!FJ104)/10000000 -> 145.61199 | J28: Market Place | K28: =('Consolidated - P&L'!FM104)/10000000 -> 0 | L28: =('Consolidated - P&L'!FN104)/10000000 -> 0 | M28: =('Consolidated - P&L'!FO104)/10000000 -> 0 | N28: =('Consolidated - P&L'!FP104)/10000000 -> 0 | O28: =('Consolidated - P&L'!FQ104)/10000000 -> 0 | P28: =('Consolidated - P&L'!FR104)/10000000 -> 0
B29: Screen Pro + Accessories | C29: =('Consolidated - P&L'!FE105)/10000000 -> 7.4517943 | D29: =('Consolidated - P&L'!FF105)/10000000 -> 9.6409796 | E29: =('Consolidated - P&L'!FG105)/10000000 -> 13.078534 | F29: =('Consolidated - P&L'!FH105)/10000000 -> 13.394705 | G29: =('Consolidated - P&L'!FI105)/10000000 -> 13.955344 | H29: =('Consolidated - P&L'!FJ105)/10000000 -> 14.409844 | J29: Screen Pro + Accessories | K29: =('Consolidated - P&L'!FM105)/10000000 -> 0 | L29: =('Consolidated - P&L'!FN105)/10000000 -> 0 | M29: =('Consolidated - P&L'!FO105)/10000000 -> 0 | N29: =('Consolidated - P&L'!FP105)/10000000 -> 0 | O29: =('Consolidated - P&L'!FQ105)/10000000 -> 0 | P29: =('Consolidated - P&L'!FR105)/10000000 -> 0
B30: Enterprise Sales | C30: =('Consolidated - P&L'!FE106)/10000000 -> 1.4942548 | D30: =('Consolidated - P&L'!FF106)/10000000 -> 2.7364487 | E30: =('Consolidated - P&L'!FG106)/10000000 -> 3.8998185 | F30: =('Consolidated - P&L'!FH106)/10000000 -> 3.8998185 | G30: =('Consolidated - P&L'!FI106)/10000000 -> 3.8998185 | H30: =('Consolidated - P&L'!FJ106)/10000000 -> 3.8998185 | J30: Enterprise Sales | K30: =('Consolidated - P&L'!FM106)/10000000 -> 0 | L30: =('Consolidated - P&L'!FN106)/10000000 -> 0 | M30: =('Consolidated - P&L'!FO106)/10000000 -> 0 | N30: =('Consolidated - P&L'!FP106)/10000000 -> 0 | O30: =('Consolidated - P&L'!FQ106)/10000000 -> 0 | P30: =('Consolidated - P&L'!FR106)/10000000 -> 0
B31: Gross Margin 1% | C31: ='Consolidated - P&L'!FE107 -> 0.17429857 | D31: ='Consolidated - P&L'!FF107 -> 0.20953932 | E31: ='Consolidated - P&L'!FG107 -> 0.20087123 | F31: ='Consolidated - P&L'!FH107 -> 0.19743053 | G31: ='Consolidated - P&L'!FI107 -> 0.19750476 | H31: ='Consolidated - P&L'!FJ107 -> 0.19714821 | J31: Gross Margin 1% | K31: ='Consolidated - P&L'!FM107 -> 0 | L31: ='Consolidated - P&L'!FN107 -> 0 | M31: ='Consolidated - P&L'!FO107 -> 0 | N31: ='Consolidated - P&L'!FP107 -> 0 | O31: ='Consolidated - P&L'!FQ107 -> 0 | P31: ='Consolidated - P&L'!FR107 -> 0
B32: Gross Margin 1% w/o MP | C32: ='Consolidated - P&L'!FE108 -> 0.12898308 | D32: ='Consolidated - P&L'!FF108 -> 0.16345402 | E32: ='Consolidated - P&L'!FG108 -> 0.16086887 | F32: ='Consolidated - P&L'!FH108 -> 0.15673905 | G32: ='Consolidated - P&L'!FI108 -> 0.15736431 | H32: ='Consolidated - P&L'!FJ108 -> 0.15770005 | J32: Gross Margin 1% w/o MP | K32: ='Consolidated - P&L'!FM108 -> 0 | L32: ='Consolidated - P&L'!FN108 -> 0 | M32: ='Consolidated - P&L'!FO108 -> 0 | N32: ='Consolidated - P&L'!FP108 -> 0 | O32: ='Consolidated - P&L'!FQ108 -> 0 | P32: ='Consolidated - P&L'!FR108 -> 0
B34: Gross Margin 2 | C34: =('Consolidated - P&L'!FE110)/10000000 -> 161.61025 | D34: =('Consolidated - P&L'!FF110)/10000000 -> 226.93981 | E34: =('Consolidated - P&L'!FG110)/10000000 -> 319.86178 | F34: =('Consolidated - P&L'!FH110)/10000000 -> 403.55687 | G34: =('Consolidated - P&L'!FI110)/10000000 -> 491.07039 | H34: =('Consolidated - P&L'!FJ110)/10000000 -> 573.29335 | J34: Gross Margin 2 | K34: =C34/C$12 -> 0.16138788 | L34: =D34/D$12 -> 0.19591726 | M34: =E34/E$12 -> 0.18605755 | N34: =F34/F$12 -> 0.184556 | O34: =G34/G$12 -> 0.18475103 | P34: =H34/H$12 -> 0.18439103
B35: Non- Repair | C35: =('Consolidated - P&L'!FE111)/10000000 -> 14.125598 | D35: =('Consolidated - P&L'!FF111)/10000000 -> 25.048841 | E35: =('Consolidated - P&L'!FG111)/10000000 -> 40.444667 | F35: =('Consolidated - P&L'!FH111)/10000000 -> 50.238811 | G35: =('Consolidated - P&L'!FI111)/10000000 -> 71.102616 | H35: =('Consolidated - P&L'!FJ111)/10000000 -> 95.188413 | J35: Non- Repair | K35: =('Consolidated - P&L'!FM111)/10000000 -> 0 | L35: =('Consolidated - P&L'!FN111)/10000000 -> 0 | M35: =('Consolidated - P&L'!FO111)/10000000 -> 0 | N35: =('Consolidated - P&L'!FP111)/10000000 -> 0 | O35: =('Consolidated - P&L'!FQ111)/10000000 -> 0 | P35: =('Consolidated - P&L'!FR111)/10000000 -> 0
B36: Refurbished | C36: =('Consolidated - P&L'!FE112)/10000000 -> 86.440968 | D36: =('Consolidated - P&L'!FF112)/10000000 -> 125.70032 | E36: =('Consolidated - P&L'!FG112)/10000000 -> 180.48463 | F36: =('Consolidated - P&L'!FH112)/10000000 -> 230.5076 | G36: =('Consolidated - P&L'!FI112)/10000000 -> 275.49349 | H36: =('Consolidated - P&L'!FJ112)/10000000 -> 314.18329 | J36: Refurbished | K36: =('Consolidated - P&L'!FM112)/10000000 -> 0 | L36: =('Consolidated - P&L'!FN112)/10000000 -> 0 | M36: =('Consolidated - P&L'!FO112)/10000000 -> 0 | N36: =('Consolidated - P&L'!FP112)/10000000 -> 0 | O36: =('Consolidated - P&L'!FQ112)/10000000 -> 0 | P36: =('Consolidated - P&L'!FR112)/10000000 -> 0
B37: Market Place | C37: =('Consolidated - P&L'!FE113)/10000000 -> 52.097639 | D37: =('Consolidated - P&L'!FF113)/10000000 -> 63.813216 | E37: =('Consolidated - P&L'!FG113)/10000000 -> 81.954121 | F37: =('Consolidated - P&L'!FH113)/10000000 -> 105.51593 | G37: =('Consolidated - P&L'!FI113)/10000000 -> 126.61912 | H37: =('Consolidated - P&L'!FJ113)/10000000 -> 145.61199 | J37: Market Place | K37: =('Consolidated - P&L'!FM113)/10000000 -> 0 | L37: =('Consolidated - P&L'!FN113)/10000000 -> 0 | M37: =('Consolidated - P&L'!FO113)/10000000 -> 0 | N37: =('Consolidated - P&L'!FP113)/10000000 -> 0 | O37: =('Consolidated - P&L'!FQ113)/10000000 -> 0 | P37: =('Consolidated - P&L'!FR113)/10000000 -> 0
B38: Screen Pro + Accessories | C38: =('Consolidated - P&L'!FE114)/10000000 -> 7.4517943 | D38: =('Consolidated - P&L'!FF114)/10000000 -> 9.6409796 | E38: =('Consolidated - P&L'!FG114)/10000000 -> 13.078534 | F38: =('Consolidated - P&L'!FH114)/10000000 -> 13.394705 | G38: =('Consolidated - P&L'!FI114)/10000000 -> 13.955344 | H38: =('Consolidated - P&L'!FJ114)/10000000 -> 14.409844 | J38: Screen Pro + Accessories | K38: =('Consolidated - P&L'!FM114)/10000000 -> 0 | L38: =('Consolidated - P&L'!FN114)/10000000 -> 0 | M38: =('Consolidated - P&L'!FO114)/10000000 -> 0 | N38: =('Consolidated - P&L'!FP114)/10000000 -> 0 | O38: =('Consolidated - P&L'!FQ114)/10000000 -> 0 | P38: =('Consolidated - P&L'!FR114)/10000000 -> 0
B39: Enterprise Sales | C39: =('Consolidated - P&L'!FE115)/10000000 -> 1.4942548 | D39: =('Consolidated - P&L'!FF115)/10000000 -> 2.7364487 | E39: =('Consolidated - P&L'!FG115)/10000000 -> 3.8998185 | F39: =('Consolidated - P&L'!FH115)/10000000 -> 3.8998185 | G39: =('Consolidated - P&L'!FI115)/10000000 -> 3.8998185 | H39: =('Consolidated - P&L'!FJ115)/10000000 -> 3.8998185 | J39: Enterprise Sales | K39: =('Consolidated - P&L'!FM115)/10000000 -> 0 | L39: =('Consolidated - P&L'!FN115)/10000000 -> 0 | M39: =('Consolidated - P&L'!FO115)/10000000 -> 0 | N39: =('Consolidated - P&L'!FP115)/10000000 -> 0 | O39: =('Consolidated - P&L'!FQ115)/10000000 -> 0 | P39: =('Consolidated - P&L'!FR115)/10000000 -> 0
B40: Gross Margin 2% | C40: ='Consolidated - P&L'!FE116 -> 0.16138788 | D40: ='Consolidated - P&L'!FF116 -> 0.19591726 | E40: ='Consolidated - P&L'!FG116 -> 0.18605755 | F40: ='Consolidated - P&L'!FH116 -> 0.184556 | G40: ='Consolidated - P&L'!FI116 -> 0.18475103 | H40: ='Consolidated - P&L'!FJ116 -> 0.18439103 | J40: Gross Margin 2% | K40: ='Consolidated - P&L'!FM116 -> 0 | L40: ='Consolidated - P&L'!FN116 -> 0 | M40: ='Consolidated - P&L'!FO116 -> 0 | N40: ='Consolidated - P&L'!FP116 -> 0 | O40: ='Consolidated - P&L'!FQ116 -> 0 | P40: ='Consolidated - P&L'!FR116 -> 0
